Workbook

Sheet Main Sheet - Formula Tests
A1: Formula Tests
A2: Formula | B2: Formula Text | C2: Test
A3: 0 | B3: 1 | C3: FALSE
A4: 1.23 | B4: 1234.5678 | C4: FALSE
A5: apple | B5: orange | C5: FALSE
A6: lemon | B6: lime | C6: FALSE
A7: {=A3} -> 0 | B7: A2 | C7: TRUE
A8: {=SUM(A3:B3)} -> 1 | B8: SUM(A2:B2) | C8: TRUE
A9: {=AVERAGE(1.234,123.4,1234000)} -> 411374.88 | B9: AVERAGE(1.234,123.4,1234000) | C9: TRUE
A10: {="""&A5&"" ""&B5&"""} -> "apple" "orange" | B10: """"&A4&""" """&B4&"""" | C10: TRUE
A11: {=A6&" "&B6&" melon"} -> lemon lime melon | B11: A5&" "&B5&" melon" | C11: TRUE
A12: {=A4*B4} -> 1518.5184 | B12: A3×B3 | C12: TRUE
A13: {=A3+B3-A4} -> -0.23 | B13: A2+B2-A3 | C13: TRUE
A14: {=A3+SUM(A3:B3)-SUM(A15:B15)} -> -3 | B14: A2+SUM(A2:B2)-SUM(A14:B14) | C14: TRUE
A15: {=IF(B3>0,COUNTA(A5:B6),COUNTA(A7:B7))} -> 4 | B15: IF(B2>0,COUNTA(A4:B5),COUNTA(A6:B6)) | C15: FALSE
A16: {=MEDIAN(B15,C15,C16,'Powers Sheet - Powers of Two'!A2:C3,'Powers Sheet - Powers of Two'!A$4:$C5)} -> 1536 | B16: MEDIAN(B14,C14,C15,Powers of Two::A1:C2,Powers of Two::A$3:$C4) | C16: TRUE
A17: {=_xlfn.TEXTJOIN(",",FALSE,'Main Sheet - Animal Table'!B2:D2)} -> cat,dog,hamster | B17: TEXTJOIN(",",FALSE,Animal Table::B1:D1) | C17: TRUE
A18: {=IF(OR(SUM(A15:B15)>1,SUM(A3:B3)>1),"yay","nay")} -> yay | B18: IF(OR(SUM(A14:B14)>1,SUM(A2:B2)>1),"yay","nay") | C18: FALSE
A19: {=IF(TRUE,1,0)} -> 1 | B19: IF(TRUE,1,0) | C19: FALSE
A20: {=IF(1<=2,TRUE,FALSE)} -> TRUE | B20: IF(1≤2,TRUE,FALSE) | C20: FALSE
A21: {=IF(1>=2,TRUE,FALSE)} -> FALSE | B21: IF(1≥2,TRUE,FALSE) | C21: FALSE
A22: {=IF(1<>2,TRUE,FALSE)} -> TRUE | B22: IF(1≠2,TRUE,FALSE) | C22: FALSE
A23: {=10+10*20+20} -> 230 | B23: 10+10×20+20 | C23: TRUE
A24: {=((10+10)/(20+20))%} -> 0.005 | B24: ((10+10)÷(20+20))% | C24: FALSE
A25: {=SUM(#REF!)} | B25: SUM(#REF!) | C25: FALSE
A26: {=AVERAGE(A4,1.86)} -> 1.545 | B26: AVERAGE(A3,1.86) | C26: TRUE
A27: {=COUNTA('Main Sheet - Food Table'!A3:B5)} -> 6 | B27: COUNTA(Food Table::A2:B4) | C27: TRUE
A28: {=COUNTA('Main Sheet - Food Table'!A3:$B5)} -> 6 | B28: COUNTA(Food Table::A2:$B4) | C28: TRUE
A29: {=COUNTA('Main Sheet - Food Table'!A3:B$5)} -> 6 | B29: COUNTA(Food Table::A2:B$4) | C29: TRUE
A30: {=COUNTA('Main Sheet - Food Table'!A3:$B$5)} -> 6 | B30: COUNTA(Food Table::A2:$B$4) | C30: TRUE
A31: {=COUNTA('Main Sheet - Food Table'!A$3:B5)} -> 6 | B31: COUNTA(Food Table::A$2:B4) | C31: TRUE
A32: {=COUNTA('Main Sheet - Food Table'!A$3:B$5)} -> 6 | B32: COUNTA(Food Table::A$2:B$4) | C32: TRUE
A33: {=COUNTA('Main Sheet - Food Table'!A$3:$B5)} -> 6 | B33: COUNTA(Food Table::A$2:$B4) | C33: TRUE
A34: {=COUNTA('Main Sheet - Food Table'!A$3:$B$5)} -> 6 | B34: COUNTA(Food Table::A$2:$B$4) | C34: TRUE
A35: {=COUNTA('Main Sheet - Food Table'!$A3:B5)} -> 6 | B35: COUNTA(Food Table::$A2:B4) | C35: TRUE
A36: {=COUNTA('Main Sheet - Food Table'!$A3:$B5)} -> 6 | B36: COUNTA(Food Table::$A2:$B4) | C36: TRUE
A37: {=COUNTA('Main Sheet - Food Table'!$A3:B$5)} -> 6 | B37: COUNTA(Food Table::$A2:B$4) | C37: TRUE
A38: {=COUNTA('Main Sheet - Food Table'!$A3:$B$5)} -> 6 | B38: COUNTA(Food Table::$A2:$B$4) | C38: TRUE
A39: {=COUNTA('Main Sheet - Food Table'!$A$3:B5)} -> 6 | B39: COUNTA(Food Table::$A$2:B4) | C39: TRUE
A40: {=COUNTA('Main Sheet - Food Table'!$A$3:$B5)} -> 6 | B40: COUNTA(Food Table::$A$2:$B4) | C40: TRUE
...

Sheet Main Sheet - Food Table
A1: Food Table
A2: fruit | B2: vegetable | C2: meat
A3: banana | B3: carrot | C3: lamb
A4: grape | B4: cabbage | C4: chicken
A5: apple | B5: asparagus | C5: beef
A6: orange | B6: courgette | C6: duck

Sheet Main Sheet - Food Table 2
A1: Food Table 2
A2: fruit | B2: vegetable | C2: game | D2: sauce
A3: pomegranate | B3: chard | C3: partridge | D3: salsa
A4: melon | B4: kale | C4: quail | D4: béchamel
A5: apricot | B5: celery | C5: rabbit | D5: roux
A6: lemon | B6: parsnip | C6: buffalo | D6: jus

Sheet Main Sheet - Animal Table
A1: Animal Table
A2: pet | B2: cat | C2: dog | D2: hamster
A3: safari | B3: lion | C3: giraffe | D3: antelope
A4: farm | B4: cow | C4: pig | D4: sheep
A5: insect | B5: ant | C5: beetle | D5: moth
A6: super hero | B6: howard the duck | C6: rocket racoon | D6: mighty mouse

Sheet Main Sheet - Animal Table 2
A1: Animal Table 2
A2: pet | B2: horse | C2: snake | D2: spider
A3: safari | B3: hyena | C3: cheetah | D3: rhino
A4: farm | B4: chicken | C4: goose | D4: pig
A5: flying insect | B5: bee | C5: fly | D5: ladybird
A6: super hero | B6: batman | C6: wonder woman | D6: flash

Sheet Main Sheet - Animal Table 3
A1: Animal Table 3
A2: furless | B2: pet | C2: gecko | D2: mantis | E2: ants
A3: bird | B3: safari | C3: vulture | D3: malibu stork | E3: ostrich
A4: dc | B4: justice league | C4: batman | D4: superman | E4: wonder woman
A5: water | B5: farm | C5: salmon | D5: sea bass | E5: halibut
A6: flying | B6: insect | C6: hornet | D6: dragonfly | E6: mosquito
A7: marvel | B7: x men | C7: beast | D7: storm | E7: wolverine

Sheet Main Sheet - Extra Headers
A1: Extra Headers
B2: Data1 | C2: Data2
A3: 1 | B3: apple | C3: blaze
A4: 2 | B4: brave | C4: cloud
A5: TRUE | B5: chair | C5: daisy
A6: FALSE | B6: dream | C6: earth
A7: Row | B7: inlet | C7: juice
A8: Row | B8: jelly | C8: koala
B9: kneel | C9: lunar
B10: lemon | C10: music
B11: mango | C11: nerve
B12: night | C12: olive
B13: ocean | C13: proud
B14: party | C14: quiet
B15: queen | C15: raven
B16: rocky | C16: sugar
B17: sunny | C17: tiger
B18: tasty | C18: vivid

Sheet Main Sheet - Extra Column
A1: Extra Column
A2: extra
A3: token
A4: coin
A5: gold

Sheet Main Sheet - Reference Tests
A1: Reference Tests
A2: Formula | B2: Formula Text | C2: Test
A3: {=SUM('Powers Sheet - Powers of Two'!A2:C3)} -> 2016 | B3: SUM(Powers of Two::1:2) | C3: TRUE
A4: {=SUM('Powers Sheet - Powers of Two'!A$2:C3)} -> 2016 | B4: SUM(Powers of Two::$1:2) | C4: TRUE
A5: {=SUM('Powers Sheet - Powers of Two'!A2:C$3)} -> 2016 | B5: SUM(Powers of Two::1:$2) | C5: TRUE
A6: {=SUM('Powers Sheet - Powers of Two'!A$2:C$3)} -> 2016 | B6: SUM(Powers of Two::$1:$2) | C6: TRUE
A7: {=SUM('Powers Sheet - Powers of Two'!B2:C6)} -> 898752 | B7: SUM(Powers of Two::B:C) | C7: TRUE
A8: {=SUM('Powers Sheet - Powers of Two'!$B2:C6)} -> 898752 | B8: SUM(Powers of Two::$B:C) | C8: TRUE
A9: {=SUM('Powers Sheet - Powers of Two'!B2:$C6)} -> 898752 | B9: SUM(Powers of Two::B:$C) | C9: TRUE
A10: {=SUM('Powers Sheet - Powers of Two'!$B2:$C6)} -> 898752 | B10: SUM(Powers of Two::$B:$C) | C10: TRUE
A11: {=COUNTA('Main Sheet - Animal Table'!B2:F2)} -> 3 | B11: COUNTA(Animal Table::pet) | C11: TRUE
A12: {=COUNTA('Main Sheet - Animal Table'!B$2:F$2)} -> 3 | B12: COUNTA(Animal Table::$pet) | C12: TRUE
A13: {=COUNTA('Main Sheet - Animal Table 2'!B5:F5)} -> 3 | B13: COUNTA(flying insect) | C13: TRUE
A14: {=COUNTA('Main Sheet - Animal Table 2'!B$5:F$5)} -> 3 | B14: COUNTA(Animal Table 2::$flying insect) | C14: FALSE
A15: {=COUNTA('Main Sheet - Animal Table'!B3:F4)} -> 6 | B15: COUNTA(Animal Table::safari:farm) | C15: TRUE
A16: {=COUNTA('Main Sheet - Food Table'!A3:A6)} -> 4 | B16: COUNTA(Food Table::fruit) | C16: TRUE
A17: {=COUNTA('Main Sheet - Food Table'!$A3:$A6)} -> 4 | B17: COUNTA(Food Table::$fruit) | C17: TRUE
A18: {=COUNTA('Main Sheet - Food Table 2'!C3:C6)} -> 4 | B18: COUNTA(game) | C18: TRUE
A19: {=COUNTA('Main Sheet - Extra Column'!A3:A5)} -> 3 | B19: COUNTA(extra) | C19: TRUE
A20: {=COUNTA('Powers Sheet - Extra Column'!A3:A5)} -> 3 | B20: COUNTA(Powers Sheet::Extra Column::extra) | C20: TRUE
A21: {=COUNTA('Main Sheet - Food Table 2'!$C3:$C6)} -> 4 | B21: COUNTA(Food Table 2::$game) | C21: TRUE
A22: {=COUNTA('Main Sheet - Animal Table'!B$6:F$6)} -> 3 | B22: COUNTA(Animal Table::$super hero) | C22: TRUE
A23: {=COUNTA('Main Sheet - Animal Table 3'!C5:G7)} -> 9 | B23: COUNTA(farm:x men) | C23: TRUE
A24: {=COUNTA('Main Sheet - Animal Table 3'!C4:G5)} -> 6 | B24: COUNTA(justice league:farm) | C24: TRUE
A25: {=COUNTA('Main Sheet - Animal Table 3'!C$6:G7)} -> 6 | B25: COUNTA($insect:x men) | C25: TRUE
A26: {=COUNTA('Main Sheet - Animal Table 3'!C6:G$7)} -> 6 | B26: COUNTA(insect:$x men) | C26: TRUE
A27: {=COUNTA('Main Sheet - Animal Table 3'!C$6:G$7)} -> 6 | B27: COUNTA($insect:$x men) | C27: TRUE
A28: {=COUNTA('Main Sheet - Food Table'!A3:C3)} -> 3 | B28: COUNTA(Food Table::2:2) | C28: TRUE
A29: {=COUNTA('Main Sheet - Food Table'!A$3:C$3)} -> 3 | B29: COUNTA(Food Table::$2:$2) | C29: TRUE
A30: {=COUNTA('Main Sheet - Food Table'!A3:A6)} -> 4 | B30: COUNTA(Food Table::fruit) | C30: TRUE
A31: {=COUNTA('Main Sheet - Food Table'!$A3:$A6)} -> 4 | B31: COUNTA(Food Table::$fruit) | C31: TRUE
A32: {=COUNTA('Main Sheet - Food Table'!B3:B6)} -> 4 | B32: COUNTA(Food Table::vegetable) | C32: TRUE
A33: {=COUNTA('Main Sheet - Food Table'!A3:B6)} -> 8 | B33: COUNTA(Food Table::fruit:vegetable) | C33: TRUE
A34: {=COUNTA('Main Sheet - Food Table'!B3:C6)} -> 8 | B34: COUNTA(vegetable:meat) | C34: TRUE
A35: {=COUNTA('Main Sheet - Food Table'!$B3:C6)} -> 8 | B35: COUNTA($vegetable:meat) | C35: TRUE
A36: {=COUNTA('Main Sheet - Food Table'!B3:$C6)} -> 8 | B36: COUNTA(vegetable:$meat) | C36: TRUE
A37: {=COUNTA('Main Sheet - Food Table'!$B3:$C6)} -> 8 | B37: COUNTA($vegetable:$meat) | C37: TRUE
A38: {=COUNTA('Main Sheet - Animal Table 3'!C3:G3)} -> 3 | B38: COUNTA(Animal Table 3::safari) | C38: TRUE
A39: {=COUNTA('Main Sheet - Animal Table 2'!B5:F6)} -> 6 | B39: COUNTA(flying insect:super hero) | C39: TRUE
A40: {=COUNTA('Main Sheet - Animal Table 2'!B$5:F6)} -> 6 | B40: COUNTA($flying insect:super hero) | C40: TRUE
...

Sheet Powers Sheet - Powers of Two
A1: Powers of Two
A2: {=POWER(2,5)} -> 32 | B2: {=A2*2} -> 64 | C2: {=B2*2} -> 128
A3: {=C2*2} -> 256 | B3: {=A3*2} -> 512 | C3: {=B3*2} -> 1024
A4: {=C3*2} -> 2048 | B4: {=A4*2} -> 4096 | C4: {=B4*2} -> 8192
A5: {=C4*2} -> 16384 | B5: {=A5*2} -> 32768 | C5: {=B5*2} -> 65536
A6: {=C5*2} -> 131072 | B6: {=A6*2} -> 262144 | C6: {=B6*2} -> 524288

Sheet Powers Sheet - Food Table 4
A1: Food Table 4
A2: fruit | B2: vegetable | C2: game | D2: fish
A3: pomegranate | B3: chard | C3: partridge | D3: salmon
A4: melon | B4: kale | C4: quail | D4: trout
A5: apricot | B5: celery | C5: rabbit | D5: cod
A6: lemon | B6: parsnip | C6: buffalo | D6: haddock

Sheet Powers Sheet - Food Table
A1: Food Table
A2: fruit | B2: vegetable | C2: game | D2: fish
A3: pomegranate | B3: chard | C3: partridge | D3: salmon
A4: melon | B4: kale | C4: quail | D4: trout
A5: apricot | B5: celery | C5: rabbit | D5: cod
A6: lemon | B6: parsnip | C6: buffalo | D6: haddock

Sheet Powers Sheet - Extra Column
A1: Extra Column
A2: extra | B2: extra2
A3: token | B3: copper
A4: coin | B4: aluminium
A5: gold | B5: carbon

Sheet Powers Sheet - Countries
A1: Countries
B2: sport | C2: attraction | D2: city
A3: usa | B3: baseball | C3: disneyland | D3: washington
A4: england | B4: cricket | C4: stonehenge | D4: manchester
A5: ireland | B5: hurling | C5: moher | D5: cork
