Workbook
Name Amounts: 'Source Data'!$B$1:$B$4
Name Chosen: 'O''Brien'!$A$1
Name CommaAlias: CommaConstant
Name CommaConstant: "Hello, world"
Name ErrorConstant: #N/A
Name FlagConstant: TRUE
Name Keys: 'Source Data'!$A$1:$A$4
Name LocalAmount: 'Source Data'!$B$2
Name RefErrorConstant: 'O''Brien'!#REF!
Name RefTextConstant: "contains #REF!"
Name Shadowed: 5
Name Shadowed: 7
Name Shadowed: 100
Name TaxAlias: TaxRate
Name TaxRate: 0.2
Name TextConstant: "say ""hello"""
Name TextExpression: "a"&"b"

Sheet O'Brien
A1: 7

Sheet Source Data
A1: alpha | B1: 10 | D1: =NA() -> #N/A
A2: Beta | B2: 20
A3: gamma | B3: 30
A4: Delta | B4: 40

Sheet Expressions
A1: SUM(Amounts) | B1: =SUM(Amounts) -> 100 | C1: =_xlfn.CONCAT(TextExpression) -> ab
A2: SUM(Amounts)+ROUND(1.255,2) | B2: =SUM(Amounts)+ROUND(1.255,2) -> 101.26
A3: AVERAGE(Amounts) | B3: =AVERAGE(Amounts) -> 25
A4: IF(SUM(Amounts)>50,SUMIF(Keys,"Beta",Amounts),0) | B4: =IF(SUM(Amounts)>50,SUMIF(Keys,"Beta",Amounts),0) -> 20
A5: COUNTIF(Keys,"*a*") | B5: =COUNTIF(Keys,"*a*") -> 4
A6: SUMIF(Amounts,">20",Amounts) | B6: =SUMIF(Amounts,">20",Amounts) -> 70
A7: SUMIFS(Amounts,Keys,"*a*",Amounts,">=20") | B7: =SUMIFS(Amounts,Keys,"*a*",Amounts,">=20") -> 90
A8: COUNTIFS(Keys,"*a*",Amounts,"<40") | B8: =COUNTIFS(Keys,"*a*",Amounts,"<40") -> 3
A9: AVERAGEIF(Amounts,">=20",Amounts) | B9: =AVERAGEIF(Amounts,">=20",Amounts) -> 30
A10: MINIFS(Amounts,Keys,"*a*") | B10: =_xlfn.MINIFS(Amounts,Keys,"*a*") -> 10
A11: MAXIFS(Amounts,Keys,"*a*") | B11: =_xlfn.MAXIFS(Amounts,Keys,"*a*") -> 40
A12: INDEX(Amounts,MATCH("gamma",Keys,0)) | B12: =INDEX(Amounts,MATCH("gamma",Keys,0)) -> 30
A13: VLOOKUP("Beta",'Source Data'!A1:B4,2,FALSE) | B13: =VLOOKUP("Beta",'Source Data'!A1:B4,2,FALSE) -> 20
A14: XLOOKUP("gamma",Keys,Amounts) | B14: =_xlfn.XLOOKUP("gamma",Keys,Amounts) -> 30
A15: XLOOKUP("missing",Keys,Amounts,"fallback") | B15: =_xlfn.XLOOKUP("missing",Keys,Amounts,"fallback") -> fallback
A16: IFERROR(VLOOKUP("missing",'Source Data'!A1:B4,2,FALSE),99) | B16: =IFERROR(VLOOKUP("missing",'Source Data'!A1:B4,2,FALSE),99) -> 99
A17: ROUND(SUM(Amounts)*TaxRate,2) | B17: =ROUND(SUM(Amounts)*TaxRate,2) -> 20
A18: LocalAmount+Chosen | B18: =LocalAmount+Chosen -> 27
A19: O''Brien'!A1*2 | B19: ='O''Brien'!A1*2 -> 14
A20: SUM('Source Data'!B1:B4)+'O''Brien'!A1 | B20: =SUM('Source Data'!B1:B4)+'O''Brien'!A1 -> 107
A21: CONCAT("total=",SUM(Amounts)) | B21: =_xlfn.CONCAT("total=",SUM(Amounts)) -> total=100
A22: TEXTJOIN("|",TRUE,Keys) | B22: =_xlfn.TEXTJOIN("|",TRUE,Keys) -> alpha|Beta|gamma|Delta
A23: UPPER(LEFT(INDEX(Keys,2),2))&LOWER(RIGHT(INDEX(Keys,3),2)) | B23: =UPPER(LEFT(INDEX(Keys,2),2))&LOWER(RIGHT(INDEX(Keys,3),2)) -> BEma
A24: SUBSTITUTE(TRIM(" Alpha Beta ")," ","_") | B24: =SUBSTITUTE(TRIM(" Alpha Beta ")," ","_") -> Alpha_Beta
A25: LEN(REPT("ab",3)) | B25: =LEN(REPT("ab",3)) -> 6
A26: EXACT(LOWER("ALPHA"),INDEX(Keys,1)) | B26: =EXACT(LOWER("ALPHA"),INDEX(Keys,1)) -> TRUE
A27: FIND("a","Alpha",2) | B27: =FIND("a","Alpha",2) -> 5
A28: SEARCH("B?ta","Alpha Beta") | B28: =SEARCH("B?ta","Alpha Beta") -> 7
A29: VALUE("123.5")+1 | B29: =VALUE("123.5")+1 -> 124.5
A30: TEXT(1234.5,"0.00") | B30: =TEXT(1234.5,"0.00") -> 1234.50
A31: ROUND(-1.255,2) | B31: =ROUND(-1.255,2) -> -1.26
A32: ROUNDUP(-1.251,2) | B32: =ROUNDUP(-1.251,2) -> -1.26
A33: ROUNDDOWN(-1.259,2) | B33: =ROUNDDOWN(-1.259,2) -> -1.25
A34: TRUNC(-2.9) | B34: =TRUNC(-2.9) -> -2
A35: INT(-2.9) | B35: =INT(-2.9) -> -3
A36: MOD(-7,3) | B36: =MOD(-7,3) -> 2
A37: MROUND(7,2) | B37: =MROUND(7,2) -> 8
A38: CEILING.MATH(-2.5) | B38: =_xlfn.CEILING.MATH(-2.5) -> -2
A39: FLOOR.MATH(-2.5) | B39: =_xlfn.FLOOR.MATH(-2.5) -> -3
A40: SQRT(81)+POWER(2,3) | B40: =SQRT(81)+POWER(2,3) -> 17
...
