Workbook
Name Calc: SUM(Data!$A$1:$A$6)*2
Name Nested: Calc/2+1
Name EmptyKey: 'Keys'!$H$1

Sheet Data
A1: 10 | B1: ten | C1: Alpha | D1: 50 | E1: fifty | F1: 1 | G1: N
A2: 20 | B2: first20 | C2: Alpine | D2: 40 | E2: forty | F2: 1 | G2: T
A3: 20 | B3: last20 | C3: Beta | D3: 30 | E3: thirty | F3: TRUE | G3: B
A4: 30 | B4: thirty | C4: B?ta | D4: 20 | E4: first20 | F4: FALSE | G4: F
A5: 40 | B5: forty | C5: B*ta | D5: 20 | E5: last20 | G5: empty
A6: 50 | B6: fifty | C6: ~tail | D6: 10 | E6: ten | F6: =NA() | G6: E

Sheet Report
A1: =MATCH(20,Data!A1:A6) | D1: MATCH(20,Data!A1:A6)
A11: =MATCH(20,Data!A1:A6,0) | D11: MATCH(20,Data!A1:A6,0)
A21: =MATCH(21,Data!A1:A6,1) | D21: MATCH(21,Data!A1:A6,1)
A31: =MATCH(21,Data!D1:D6,-1) | D31: MATCH(21,Data!D1:D6,-1)
A41: =VLOOKUP(20,Data!A1:B6,2) | D41: VLOOKUP(20,Data!A1:B6,2)
A51: =VLOOKUP(21,Data!A1:B6,2,TRUE) | D51: VLOOKUP(21,Data!A1:B6,2,TRUE)
A61: =VLOOKUP("Al*",Data!C1:G6,5,FALSE) | D61: VLOOKUP("Al*",Data!C1:G6,5,FALSE)
A71: =MATCH("B~?ta",Data!C1:C6,0) | D71: MATCH("B~?ta",Data!C1:C6,0)
A81: =MATCH("B~*ta",Data!C1:C6,0) | D81: MATCH("B~*ta",Data!C1:C6,0)
A91: =_xlfn.XMATCH("Al*",Data!C1:C6,2) | D91: XMATCH("Al*",Data!C1:C6,2)
A101: =_xlfn.XMATCH("Al*",Data!C1:C6,2,-1) | D101: XMATCH("Al*",Data!C1:C6,2,-1)
A111: =_xlfn.XLOOKUP("B~?ta",Data!C1:C6,Data!B1:B6,,2) | D111: XLOOKUP("B~?ta",Data!C1:C6,Data!B1:B6,,2)
A121: =_xlfn.XMATCH(20,Data!A1:A6,0,2) | D121: XMATCH(20,Data!A1:A6,0,2)
A131: =_xlfn.XMATCH(20,Data!D1:D6,0,-2) | D131: XMATCH(20,Data!D1:D6,0,-2)
A141: =_xlfn.XMATCH(21,Data!A1:A6,-1,2) | D141: XMATCH(21,Data!A1:A6,-1,2)
A151: =_xlfn.XMATCH(21,Data!D1:D6,1,-2) | D151: XMATCH(21,Data!D1:D6,1,-2)
A161: =_xlfn.XLOOKUP(21,Data!A1:A6,Data!B1:B6,,-1,2) | D161: XLOOKUP(21,Data!A1:A6,Data!B1:B6,,-1,2)
A171: =_xlfn.XLOOKUP(21,Data!D1:D6,Data!E1:E6,,1,-2) | D171: XLOOKUP(21,Data!D1:D6,Data!E1:E6,,1,-2)
A181: =_xlfn.XMATCH("Al*",Data!C1:C6,2,2) | D181: XMATCH("Al*",Data!C1:C6,2,2)
A191: =MATCH(1,Data!F1:F6,0) | D191: MATCH(1,Data!F1:F6,0)
A201: =MATCH("1",Data!F1:F6,0) | D201: MATCH("1",Data!F1:F6,0)
A211: =MATCH(TRUE,Data!F1:F6,0) | D211: MATCH(TRUE,Data!F1:F6,0)
A221: =MATCH(FALSE,Data!F1:F6,0) | D221: MATCH(FALSE,Data!F1:F6,0)
A231: =_xlfn.XLOOKUP(1,Data!F1:F6,Data!G1:G6) | D231: XLOOKUP(1,Data!F1:F6,Data!G1:G6)
A241: =_xlfn.XLOOKUP("1",Data!F1:F6,Data!G1:G6) | D241: XLOOKUP("1",Data!F1:F6,Data!G1:G6)
A251: =_xlfn.XLOOKUP(TRUE,Data!F1:F6,Data!G1:G6) | D251: XLOOKUP(TRUE,Data!F1:F6,Data!G1:G6)
A261: =MATCH(30,{10,20,30},0) | D261: MATCH(30,{10,20,30},0)
A271: =SUM(INDEX(Data!A1:B6,0,1)) | D271: SUM(INDEX(Data!A1:B6,0,1))
A281: =SUM(INDEX(Data!A1:B6,3,0)) | D281: SUM(INDEX(Data!A1:B6,3,0))
A291: =INDEX(Data!A1:B6,0,1) | D291: INDEX(Data!A1:B6,0,1)
A301: =INDEX(Data!A1:B6,3,0) | D301: INDEX(Data!A1:B6,3,0)
A311: =INDEX({10,20;30,40},0,2) | D311: INDEX({10,20;30,40},0,2)
A321: =_xlfn.XLOOKUP(20,Data!A1:A6,Data!B1:C6) | D321: XLOOKUP(20,Data!A1:A6,Data!B1:C6)
A331: =IFERROR(SUM(INDEX(Data!A1:B6,0,NA())),99) | D331: IFERROR(SUM(INDEX(Data!A1:B6,0,NA())),99)
A341: =Calc+Nested | D341: Calc+Nested
A351: =VLOOKUP(21,Data!A1:B6,2,) | D351: VLOOKUP(21,Data!A1:B6,2,)
A361: =MATCH(20,Data!A1:A6,) | D361: MATCH(20,Data!A1:A6,)
A371: =VLOOKUP(21,Data!A1:B6,2,0.00000001) | D371: VLOOKUP(21,Data!A1:B6,2,0.00000001)
A381: =INDEX(Data!A1:B6,3) | D381: INDEX(Data!A1:B6,3)
A391: =INDEX(Data!A1:B6,3,) | D391: INDEX(Data!A1:B6,3,)
...

Sheet Keys
B1: 100 | E1: 5 | F1: 0 | J1: -5 | L1: 5
A2: 5 | B2: 500 | D2: 100 | E2: 500 | F2: 200 | J2: 0 | L2: 0
A3: 0 | B3: 200 | J3: 5 | L3: -5
A4: 0
A5: FALSE
