Workbook

Sheet LookupEdges
A1: =GETPIVOTDATA("Metric",Sum!A1,"Region","West","Product","A") -> 0
A2: =GETPIVOTDATA("Amount",Sum!A1) -> 48
A3: =GETPIVOTDATA("Count",ErrorGroups!A1) -> #N/A
A4: =GETPIVOTDATA("CountNumbers",ErrorGroups!A1) -> #N/A
A5: =GETPIVOTDATA("Metric",Sum!B4,"Region","North") -> 28
A6: =GETPIVOTDATA("Metric",Sum!A1:D6,"Product","A") -> 13
A7: =GETPIVOTDATA("Metric",Sum!Z1) -> #REF!
A8: =GETPIVOTDATA("Metric",Sum!A1,"Region","North","Region","North") -> 28
A9: =GETPIVOTDATA("Metric",Sum!A1,"Region","North","Region","South") -> #REF!
A10: =GETPIVOTDATA("Metric",Sum!A1,"Region","north") -> 28
A11: =GETPIVOTDATA("Metric",Sum!A1,"notafield","A") -> #REF!
A12: =GETPIVOTDATA("missing",Sum!A1) -> #REF!
A13: =GETPIVOTDATA("Count",ErrorGroups!A1,"Group","TextNumber") -> 1
A14: =IFERROR(GETPIVOTDATA("Metric",Sum!Z1),77) -> 77
A15: =GETPIVOTDATA("Metric",Sum!A1,"Region",Source!A2) -> 28
A16: =GETPIVOTDATA("Metric",Sum!A1,"Region","West") -> 0
A17: =GETPIVOTDATA("Metric",Sum!A1,"Region","West","Product","B") -> 0
A18: =GETPIVOTDATA("Metric",Sum!A1,"Product","a") -> 13
A19: =GETPIVOTDATA("Count",ErrorGroups!A1,"Group","Literal") -> 1
A20: =GETPIVOTDATA("CountNumbers",ErrorGroups!A1,"Group","Literal") -> 0
A21: =GETPIVOTDATA("Metric",Sum!A1,"Product",1) -> #REF!
A22: =FALSE() -> FALSE

Sheet ErrorGroups
A1: Row Labels | B1: Sum | C1: Count | D1: CountNumbers | E1: Average | F1: Minimum | G1: Maximum | H1: Product | I1: StandardDeviation | J1: StandardDeviationP | K1: Variance | L1: VarianceP
A2: Boolean | B2: 0 | C2: 1 | D2: 0 | E2: #DIV/0! | F2: 0 | G2: 0 | H2: 0 | I2: #DIV/0! | J2: #DIV/0! | K2: #DIV/0! | L2: #DIV/0!
A3: Empty
A4: Error | B4: #N/A | C4: 2 | D4: 1 | E4: #N/A | F4: #N/A | G4: #N/A | H4: #N/A | I4: #N/A | J4: #N/A | K4: #N/A | L4: #N/A
A5: Literal | B5: 0 | C5: 1 | D5: 0 | E5: #DIV/0! | F5: 0 | G5: 0 | H5: 0 | I5: #DIV/0! | J5: #DIV/0! | K5: #DIV/0! | L5: #DIV/0!
A6: Single | B6: 5 | C6: 1 | D6: 1 | E6: 5 | F6: 5 | G6: 5 | H6: 5 | I6: #DIV/0! | J6: 0 | K6: #DIV/0! | L6: 0
A7: TextNumber | B7: 0 | C7: 1 | D7: 0 | E7: #DIV/0! | F7: 0 | G7: 0 | H7: 0 | I7: #DIV/0! | J7: #DIV/0! | K7: #DIV/0! | L7: #DIV/0!
A8: Grand Total | B8: #N/A | C8: #N/A | D8: #N/A | E8: #N/A | F8: #N/A | G8: #N/A | H8: #N/A | I8: #N/A | J8: #N/A | K8: #N/A | L8: #N/A

Sheet ErrorSource
A1: Group | B1: Amount
A2: Error | B2: =NA() -> #N/A
A3: Error | B3: 3
A4: Literal | B4: ="#N/A" -> #N/A
A5: Empty
A6: Single | B6: 5
A7: Boolean | B7: =TRUE() -> TRUE
A8: TextNumber | B8: ="12" -> 12

Sheet VarianceP
A1: Metric | B1: Product
A2: Region | B2: A | C2: B | D2: Grand Total
A3: North | B3: 36 | C3: 0 | D3: 80.888889
A4: South | B4: 0 | C4: 0 | D4: 25
A5: West
A6: Grand Total | B6: 24.222222 | C6: 6.25 | D6: 58.64

Sheet Variance
A1: Metric | B1: Product
A2: Region | B2: A | C2: B | D2: Grand Total
A3: North | B3: 72 | C3: #DIV/0! | D3: 121.33333
A4: South | B4: #DIV/0! | C4: #DIV/0! | D4: 50
A5: West
A6: Grand Total | B6: 36.333333 | C6: 12.5 | D6: 73.3

Sheet StandardDeviationP
A1: Metric | B1: Product
A2: Region | B2: A | C2: B | D2: Grand Total
A3: North | B3: 6 | C3: 0 | D3: 8.993825
A4: South | B4: 0 | C4: 0 | D4: 5
A5: West
A6: Grand Total | B6: 4.9216077 | C6: 2.5 | D6: 7.6576759

Sheet StandardDeviation
A1: Metric | B1: Product
A2: Region | B2: A | C2: B | D2: Grand Total
A3: North | B3: 8.4852814 | C3: #DIV/0! | D3: 11.015141
A4: South | B4: #DIV/0! | C4: #DIV/0! | D4: 7.0710678
A5: West
A6: Grand Total | B6: 6.0277138 | C6: 3.5355339 | D6: 8.5615419

Sheet Product
A1: Metric | B1: Product
A2: Region | B2: A | C2: B | D2: Grand Total
A3: North | B3: -20 | C3: 20 | D3: -400
A4: South | B4: 5 | C4: 15 | D4: 75
A5: West
A6: Grand Total | B6: -100 | C6: 300 | D6: -30000

Sheet Maximum
A1: Metric | B1: Product
A2: Region | B2: A | C2: B | D2: Grand Total
A3: North | B3: 10 | C3: 20 | D3: 20
A4: South | B4: 5 | C4: 15 | D4: 15
A5: West
A6: Grand Total | B6: 10 | C6: 20 | D6: 20

Sheet Minimum
A1: Metric | B1: Product
A2: Region | B2: A | C2: B | D2: Grand Total
A3: North | B3: -2 | C3: 20 | D3: -2
A4: South | B4: 5 | C4: 15 | D4: 5
A5: West
A6: Grand Total | B6: -2 | C6: 15 | D6: -2

Sheet Average
A1: Metric | B1: Product
A2: Region | B2: A | C2: B | D2: Grand Total
A3: North | B3: 4 | C3: 20 | D3: 9.3333333
A4: South | B4: 5 | C4: 15 | D4: 10
A5: West
A6: Grand Total | B6: 4.3333333 | C6: 17.5 | D6: 9.6

Sheet CountNumbers
A1: Metric | B1: Product
A2: Region | B2: A | C2: B | D2: Grand Total
A3: North | B3: 2 | C3: 1 | D3: 3
A4: South | B4: 1 | C4: 1 | D4: 2
A5: West
A6: Grand Total | B6: 3 | C6: 2 | D6: 5

Sheet Count
A1: Metric | B1: Product
A2: Region | B2: A | C2: B | D2: Grand Total
A3: North | B3: 2 | C3: 2 | D3: 4
A4: South | B4: 2 | C4: 1 | D4: 3
A5: West
A6: Grand Total | B6: 4 | C6: 3 | D6: 7

Sheet Sum
A1: Metric | B1: Product
A2: Region | B2: A | C2: B | D2: Grand Total
A3: North | B3: 8 | C3: 20 | D3: 28
A4: South | B4: 5 | C4: 15 | D4: 20
A5: West
A6: Grand Total | B6: 13 | C6: 35 | D6: 48

Sheet Lookups
A1: Sum | B1: =GETPIVOTDATA("Metric",Sum!A1) -> 48
A2: Sum | B2: =GETPIVOTDATA("Metric",Sum!A1,"Region","North") -> 28
A3: Sum | B3: =GETPIVOTDATA("Metric",Sum!A1,"Region","South") -> 20
A4: Sum | B4: =GETPIVOTDATA("Metric",Sum!A1,"Region","West") -> 0
A5: Sum | B5: =GETPIVOTDATA("Metric",Sum!A1,"Product","A") -> 13
A6: Sum | B6: =GETPIVOTDATA("Metric",Sum!A1,"Product","B") -> 35
A7: Sum | B7: =GETPIVOTDATA("Metric",Sum!A1,"Region","North","Product","A") -> 8
A8: Sum | B8: =GETPIVOTDATA("Metric",Sum!A1,"Region","South","Product","B") -> 15
A9: Sum | B9: =GETPIVOTDATA("Metric",Sum!A1,"Region","missing") -> #REF!
A10: Count | B10: =GETPIVOTDATA("Metric",Count!A1) -> 7
A11: Count | B11: =GETPIVOTDATA("Metric",Count!A1,"Region","North") -> 4
A12: Count | B12: =GETPIVOTDATA("Metric",Count!A1,"Region","South") -> 3
A13: Count | B13: =GETPIVOTDATA("Metric",Count!A1,"Region","West") -> 0
A14: Count | B14: =GETPIVOTDATA("Metric",Count!A1,"Product","A") -> 4
A15: Count | B15: =GETPIVOTDATA("Metric",Count!A1,"Product","B") -> 3
A16: Count | B16: =GETPIVOTDATA("Metric",Count!A1,"Region","North","Product","A") -> 2
A17: Count | B17: =GETPIVOTDATA("Metric",Count!A1,"Region","South","Product","B") -> 1
A18: Count | B18: =GETPIVOTDATA("Metric",Count!A1,"Region","missing") -> #REF!
A19: CountNumbers | B19: =GETPIVOTDATA("Metric",CountNumbers!A1) -> 5
A20: CountNumbers | B20: =GETPIVOTDATA("Metric",CountNumbers!A1,"Region","North") -> 3
A21: CountNumbers | B21: =GETPIVOTDATA("Metric",CountNumbers!A1,"Region","South") -> 2
A22: CountNumbers | B22: =GETPIVOTDATA("Metric",CountNumbers!A1,"Region","West") -> 0
A23: CountNumbers | B23: =GETPIVOTDATA("Metric",CountNumbers!A1,"Product","A") -> 3
A24: CountNumbers | B24: =GETPIVOTDATA("Metric",CountNumbers!A1,"Product","B") -> 2
A25: CountNumbers | B25: =GETPIVOTDATA("Metric",CountNumbers!A1,"Region","North","Product","A") -> 2
A26: CountNumbers | B26: =GETPIVOTDATA("Metric",CountNumbers!A1,"Region","South","Product","B") -> 1
A27: CountNumbers | B27: =GETPIVOTDATA("Metric",CountNumbers!A1,"Region","missing") -> #REF!
A28: Average | B28: =GETPIVOTDATA("Metric",Average!A1) -> 9.6
A29: Average | B29: =GETPIVOTDATA("Metric",Average!A1,"Region","North") -> 9.3333333
A30: Average | B30: =GETPIVOTDATA("Metric",Average!A1,"Region","South") -> 10
A31: Average | B31: =GETPIVOTDATA("Metric",Average!A1,"Region","West") -> 0
A32: Average | B32: =GETPIVOTDATA("Metric",Average!A1,"Product","A") -> 4.3333333
A33: Average | B33: =GETPIVOTDATA("Metric",Average!A1,"Product","B") -> 17.5
A34: Average | B34: =GETPIVOTDATA("Metric",Average!A1,"Region","North","Product","A") -> 4
A35: Average | B35: =GETPIVOTDATA("Metric",Average!A1,"Region","South","Product","B") -> 15
A36: Average | B36: =GETPIVOTDATA("Metric",Average!A1,"Region","missing") -> #REF!
A37: Minimum | B37: =GETPIVOTDATA("Metric",Minimum!A1) -> -2
A38: Minimum | B38: =GETPIVOTDATA("Metric",Minimum!A1,"Region","North") -> -2
A39: Minimum | B39: =GETPIVOTDATA("Metric",Minimum!A1,"Region","South") -> 5
A40: Minimum | B40: =GETPIVOTDATA("Metric",Minimum!A1,"Region","West") -> 0
...

Sheet Source
A1: Region | B1: Product | C1: Amount | D1: Units
A2: North | B2: A | C2: 10 | D2: 2
A3: North | B3: B | C3: 20 | D3: 3
A4: South | B4: A | C4: 5 | D4: 1
A5: South | B5: B | C5: 15 | D5: 4
A6: North | B6: A | C6: -2 | D6: 1
A7: West | B7: B | D7: 5
A8: South | B8: A | C8: pending | D8: 2
A9: North | B9: B | C9: TRUE | D9: 1
