Workbook

Sheet CollapsedManyRow
D1: Product | E1: Channel
D2: A | F2: A Total | G2: B | I2: B Total | J2: C | K2: C Total | L2: Grand Total
A3: Region | B3: City | C3: Values | D3: Retail | E3: Web | G3: Retail | H3: Web | J3: Direct
A4: North | C4: Revenue | D4: 13 | E4: 0 | F4: 13 | G4: 5 | H4: -2 | I4: 3 | L4: 16
C5: AvgUnits | D5: 4 | E5: 1 | F5: 3 | G5: 1 | H5: 1 | I5: 1 | L5: 2.2
C6: Entries | D6: 2 | E6: 1 | F6: 3 | G6: 1 | H6: 1 | I6: 2 | L6: 5
A7: South | B7: East | C7: Revenue | D7: 0 | E7: 8 | F7: 8 | H7: 20 | I7: 20 | L7: 28
C8: AvgUnits | D8: 2 | E8: 2 | F8: 2 | H8: 3 | I8: 3 | L8: 2.3333333
C9: Entries | D9: 1 | E9: 1 | F9: 2 | H9: 1 | I9: 1 | L9: 3
B10: West | C10: Revenue | E10: 15 | F10: 15 | G10: 7 | I10: 7 | L10: 22
C11: AvgUnits | E11: 4 | F11: 4 | G11: 3 | I11: 3 | L11: 3.5
C12: Entries | E12: 1 | F12: 1 | G12: 1 | I12: 1 | L12: 2
A13: South Revenue | D13: 0 | E13: 23 | F13: 23 | G13: 7 | H13: 20 | I13: 27 | L13: 50
A14: South AvgUnits | D14: 2 | E14: 3 | F14: 2.6666667 | G14: 3 | H14: 3 | I14: 3 | L14: 2.8
A15: South Entries | D15: 1 | E15: 2 | F15: 3 | G15: 1 | H15: 1 | I15: 2 | L15: 5
A16: West | B16: East | C16: Revenue | D16: 4 | F16: 4 | L16: 4
C17: AvgUnits | D17: 2 | F17: 2 | L17: 2
C18: Entries | D18: 1 | F18: 1 | L18: 1
B19: Unique | C19: Revenue
C20: AvgUnits | J20: 5 | K20: 5 | L20: 5
C21: Entries
A22: West Revenue | D22: 4 | F22: 4 | L22: 4
A23: West AvgUnits | D23: 2 | F23: 2 | J23: 5 | K23: 5 | L23: 3.5
A24: West Entries | D24: 1 | F24: 1 | L24: 1
A25: Total Revenue | D25: 17 | E25: 23 | F25: 40 | G25: 12 | H25: 18 | I25: 30 | L25: 70
A26: Total AvgUnits | D26: 3 | E26: 2.3333333 | F26: 2.7142857 | G26: 2 | H26: 2 | I26: 2 | J26: 5 | K26: 5 | L26: 2.6666667
A27: Total Entries | D27: 4 | E27: 3 | F27: 7 | G27: 2 | H27: 2 | I27: 4 | L27: 11

Sheet CompactOuterRow
B1: Column Labels
B2: A | D2: A Total | E2: B | G2: B Total | H2: C | I2: C Total | J2: Grand Total
A3: Row Labels | B3: Retail | C3: Web | E3: Retail | F3: Web | H3: Direct
A4: Revenue
A5: North | B5: 13 | C5: 0 | D5: 13 | E5: 5 | F5: -2 | G5: 3 | J5: 16
A6: East | B6: 13 | D6: 13 | F6: -2 | G6: -2 | J6: 11
A7: West | C7: 0 | D7: 0 | E7: 5 | G7: 5 | J7: 5
A8: South | B8: 0 | C8: 23 | D8: 23 | E8: 7 | F8: 20 | G8: 27 | J8: 50
A9: East | B9: 0 | C9: 8 | D9: 8 | F9: 20 | G9: 20 | J9: 28
A10: West | C10: 15 | D10: 15 | E10: 7 | G10: 7 | J10: 22
A11: West | B11: 4 | D11: 4 | J11: 4
A12: East | B12: 4 | D12: 4 | J12: 4
A13: Unique
A14: AvgUnits
A15: North | B15: 4 | C15: 1 | D15: 3 | E15: 1 | F15: 1 | G15: 1 | J15: 2.2
A16: East | B16: 4 | D16: 4 | F16: 1 | G16: 1 | J16: 3
A17: West | C17: 1 | D17: 1 | E17: 1 | G17: 1 | J17: 1
A18: South | B18: 2 | C18: 3 | D18: 2.6666667 | E18: 3 | F18: 3 | G18: 3 | J18: 2.8
A19: East | B19: 2 | C19: 2 | D19: 2 | F19: 3 | G19: 3 | J19: 2.3333333
A20: West | C20: 4 | D20: 4 | E20: 3 | G20: 3 | J20: 3.5
A21: West | B21: 2 | D21: 2 | H21: 5 | I21: 5 | J21: 3.5
A22: East | B22: 2 | D22: 2 | J22: 2
A23: Unique | H23: 5 | I23: 5 | J23: 5
A24: Entries
A25: North | B25: 2 | C25: 1 | D25: 3 | E25: 1 | F25: 1 | G25: 2 | J25: 5
A26: East | B26: 2 | D26: 2 | F26: 1 | G26: 1 | J26: 3
A27: West | C27: 1 | D27: 1 | E27: 1 | G27: 1 | J27: 2
A28: South | B28: 1 | C28: 2 | D28: 3 | E28: 1 | F28: 1 | G28: 2 | J28: 5
A29: East | B29: 1 | C29: 1 | D29: 2 | F29: 1 | G29: 1 | J29: 3
A30: West | C30: 1 | D30: 1 | E30: 1 | G30: 1 | J30: 2
A31: West | B31: 1 | D31: 1 | J31: 1
A32: East | B32: 1 | D32: 1 | J32: 1
A33: Unique
A34: Total Revenue | B34: 17 | C34: 23 | D34: 40 | E34: 12 | F34: 18 | G34: 30 | J34: 70
A35: Total AvgUnits | B35: 3 | C35: 2.3333333 | D35: 2.7142857 | E35: 2 | F35: 2 | G35: 2 | H35: 5 | I35: 5 | J35: 2.6666667
A36: Total Entries | B36: 4 | C36: 3 | D36: 7 | E36: 2 | F36: 2 | G36: 4 | J36: 11

Sheet CollapsedRow
A1: Revenue | C1: Product | D1: Channel
C2: A | E2: A Total | F2: B | H2: B Total | I2: C | J2: C Total | K2: Grand Total
A3: Region | B3: City | C3: Retail | D3: Web | F3: Retail | G3: Web | I3: Direct
A4: North | C4: 13 | D4: 0 | E4: 13 | F4: 5 | G4: -2 | H4: 3 | K4: 16
A5: South | B5: East | C5: 0 | D5: 8 | E5: 8 | G5: 20 | H5: 20 | K5: 28
B6: West | D6: 15 | E6: 15 | F6: 7 | H6: 7 | K6: 22
A7: South Total | C7: 0 | D7: 23 | E7: 23 | F7: 7 | G7: 20 | H7: 27 | K7: 50
A8: West | B8: East | C8: 4 | E8: 4 | K8: 4
B9: Unique
A10: West Total | C10: 4 | E10: 4 | K10: 4
A11: Grand Total | C11: 17 | D11: 23 | E11: 40 | F11: 12 | G11: 18 | H11: 30 | K11: 70

Sheet TopSubtotalRow3
A1: Region | B1: City | C1: Product | D1: Revenue
A2: North | D2: 16
B3: East | D3: 11
C4: A | D4: 13
C5: B | D5: -2
B6: West | D6: 5
C7: A | D7: 0
C8: B | D8: 5
A9: South | D9: 50
B10: East | D10: 28
C11: A | D11: 8
C12: B | D12: 20
B13: West | D13: 22
C14: A | D14: 15
C15: B | D15: 7
A16: West | D16: 4
B17: East | D17: 4
C18: A | D18: 4
B19: Unique
C20: C
A21: Grand Total | D21: 70

Sheet OutlineManyCol
C1: Values | D1: Product | E1: Channel
C2: Revenue | K2: AvgUnits | S2: Entries | AA2: Total Revenue | AB2: Total AvgUnits | AC2: Total Entries
C3: A | E3: A Total | F3: B | H3: B Total | I3: C | J3: C Total | K3: A | M3: A Total | N3: B | P3: B Total | Q3: C | R3: C Total | S3: A | U3: A Total | V3: B | X3: B Total | Y3: C | Z3: C Total
A4: Region | B4: City | C4: Retail | D4: Web | F4: Retail | G4: Web | I4: Direct | K4: Retail | L4: Web | N4: Retail | O4: Web | Q4: Direct | S4: Retail | T4: Web | V4: Retail | W4: Web | Y4: Direct
A5: North | C5: 13 | D5: 0 | E5: 13 | F5: 5 | G5: -2 | H5: 3 | K5: 4 | L5: 1 | M5: 3 | N5: 1 | O5: 1 | P5: 1 | S5: 2 | T5: 1 | U5: 3 | V5: 1 | W5: 1 | X5: 2 | AA5: 16 | AB5: 2.2 | AC5: 5
B6: East | C6: 13 | E6: 13 | G6: -2 | H6: -2 | K6: 4 | M6: 4 | O6: 1 | P6: 1 | S6: 2 | U6: 2 | W6: 1 | X6: 1 | AA6: 11 | AB6: 3 | AC6: 3
B7: West | D7: 0 | E7: 0 | F7: 5 | H7: 5 | L7: 1 | M7: 1 | N7: 1 | P7: 1 | T7: 1 | U7: 1 | V7: 1 | X7: 1 | AA7: 5 | AB7: 1 | AC7: 2
A8: South | C8: 0 | D8: 23 | E8: 23 | F8: 7 | G8: 20 | H8: 27 | K8: 2 | L8: 3 | M8: 2.6666667 | N8: 3 | O8: 3 | P8: 3 | S8: 1 | T8: 2 | U8: 3 | V8: 1 | W8: 1 | X8: 2 | AA8: 50 | AB8: 2.8 | AC8: 5
B9: East | C9: 0 | D9: 8 | E9: 8 | G9: 20 | H9: 20 | K9: 2 | L9: 2 | M9: 2 | O9: 3 | P9: 3 | S9: 1 | T9: 1 | U9: 2 | W9: 1 | X9: 1 | AA9: 28 | AB9: 2.3333333 | AC9: 3
B10: West | D10: 15 | E10: 15 | F10: 7 | H10: 7 | L10: 4 | M10: 4 | N10: 3 | P10: 3 | T10: 1 | U10: 1 | V10: 1 | X10: 1 | AA10: 22 | AB10: 3.5 | AC10: 2
A11: West | C11: 4 | E11: 4 | K11: 2 | M11: 2 | Q11: 5 | R11: 5 | S11: 1 | U11: 1 | AA11: 4 | AB11: 3.5 | AC11: 1
B12: East | C12: 4 | E12: 4 | K12: 2 | M12: 2 | S12: 1 | U12: 1 | AA12: 4 | AB12: 2 | AC12: 1
B13: Unique | Q13: 5 | R13: 5 | AB13: 5
A14: Grand Total | C14: 17 | D14: 23 | E14: 40 | F14: 12 | G14: 18 | H14: 30 | K14: 3 | L14: 2.3333333 | M14: 2.7142857 | N14: 2 | O14: 2 | P14: 2 | Q14: 5 | R14: 5 | S14: 4 | T14: 3 | U14: 7 | V14: 2 | W14: 2 | X14: 4 | AA14: 70 | AB14: 2.6666667 | AC14: 11

Sheet CompactManyRow
B1: Column Labels
B2: A | D2: A Total | E2: B | G2: B Total | H2: C | I2: C Total | J2: Grand Total
A3: Row Labels | B3: Retail | C3: Web | E3: Retail | F3: Web | H3: Direct
A4: North
A5: Revenue
A6: East | B6: 13 | D6: 13 | F6: -2 | G6: -2 | J6: 11
A7: West | C7: 0 | D7: 0 | E7: 5 | G7: 5 | J7: 5
A8: AvgUnits
A9: East | B9: 4 | D9: 4 | F9: 1 | G9: 1 | J9: 3
A10: West | C10: 1 | D10: 1 | E10: 1 | G10: 1 | J10: 1
A11: Entries
A12: East | B12: 2 | D12: 2 | F12: 1 | G12: 1 | J12: 3
A13: West | C13: 1 | D13: 1 | E13: 1 | G13: 1 | J13: 2
A14: North Revenue | B14: 13 | C14: 0 | D14: 13 | E14: 5 | F14: -2 | G14: 3 | J14: 16
A15: North AvgUnits | B15: 4 | C15: 1 | D15: 3 | E15: 1 | F15: 1 | G15: 1 | J15: 2.2
A16: North Entries | B16: 2 | C16: 1 | D16: 3 | E16: 1 | F16: 1 | G16: 2 | J16: 5
A17: South
A18: Revenue
A19: East | B19: 0 | C19: 8 | D19: 8 | F19: 20 | G19: 20 | J19: 28
A20: West | C20: 15 | D20: 15 | E20: 7 | G20: 7 | J20: 22
A21: AvgUnits
A22: East | B22: 2 | C22: 2 | D22: 2 | F22: 3 | G22: 3 | J22: 2.3333333
A23: West | C23: 4 | D23: 4 | E23: 3 | G23: 3 | J23: 3.5
A24: Entries
A25: East | B25: 1 | C25: 1 | D25: 2 | F25: 1 | G25: 1 | J25: 3
A26: West | C26: 1 | D26: 1 | E26: 1 | G26: 1 | J26: 2
A27: South Revenue | B27: 0 | C27: 23 | D27: 23 | E27: 7 | F27: 20 | G27: 27 | J27: 50
A28: South AvgUnits | B28: 2 | C28: 3 | D28: 2.6666667 | E28: 3 | F28: 3 | G28: 3 | J28: 2.8
A29: South Entries | B29: 1 | C29: 2 | D29: 3 | E29: 1 | F29: 1 | G29: 2 | J29: 5
A30: West
A31: Revenue
A32: East | B32: 4 | D32: 4 | J32: 4
A33: Unique
A34: AvgUnits
A35: East | B35: 2 | D35: 2 | J35: 2
A36: Unique | H36: 5 | I36: 5 | J36: 5
A37: Entries
A38: East | B38: 1 | D38: 1 | J38: 1
A39: Unique
A40: West Revenue | B40: 4 | D40: 4 | J40: 4
...

Sheet NoSubtotal3
E1: Channel
A2: Region | B2: Values | C2: City | D2: Product | E2: Direct | F2: Retail | G2: Web | H2: Grand Total
A3: North | B3: Revenue | C3: East | D3: A | F3: 13 | H3: 13
D4: B | G4: -2 | H4: -2
C5: West | D5: A | G5: 0 | H5: 0
D6: B | F6: 5 | H6: 5
B7: AvgUnits | C7: East | D7: A | F7: 4 | H7: 4
D8: B | G8: 1 | H8: 1
C9: West | D9: A | G9: 1 | H9: 1
D10: B | F10: 1 | H10: 1
B11: Entries | C11: East | D11: A | F11: 2 | H11: 2
D12: B | G12: 1 | H12: 1
C13: West | D13: A | G13: 1 | H13: 1
D14: B | F14: 1 | H14: 1
A15: South | B15: Revenue | C15: East | D15: A | F15: 0 | G15: 8 | H15: 8
D16: B | G16: 20 | H16: 20
C17: West | D17: A | G17: 15 | H17: 15
D18: B | F18: 7 | H18: 7
B19: AvgUnits | C19: East | D19: A | F19: 2 | G19: 2 | H19: 2
D20: B | G20: 3 | H20: 3
C21: West | D21: A | G21: 4 | H21: 4
D22: B | F22: 3 | H22: 3
B23: Entries | C23: East | D23: A | F23: 1 | G23: 1 | H23: 2
D24: B | G24: 1 | H24: 1
C25: West | D25: A | G25: 1 | H25: 1
D26: B | F26: 1 | H26: 1
A27: West | B27: Revenue | C27: East | D27: A | F27: 4 | H27: 4
C28: Unique | D28: C
B29: AvgUnits | C29: East | D29: A | F29: 2 | H29: 2
C30: Unique | D30: C | E30: 5 | H30: 5
B31: Entries | C31: East | D31: A | F31: 1 | H31: 1
C32: Unique | D32: C
A33: Total Revenue | F33: 29 | G33: 41 | H33: 70
A34: Total AvgUnits | E34: 5 | F34: 2.6666667 | G34: 2.2 | H34: 2.6666667
A35: Total Entries | F35: 6 | G35: 5 | H35: 11

Sheet NoGrand
A1: Revenue | C1: Product | D1: Channel
C2: A | E2: A Total | F2: B | H2: B Total | I2: C | J2: C Total
A3: Region | B3: City | C3: Retail | D3: Web | F3: Retail | G3: Web | I3: Direct
A4: North | B4: East | C4: 13 | E4: 13 | G4: -2 | H4: -2
B5: West | D5: 0 | E5: 0 | F5: 5 | H5: 5
A6: North Total | C6: 13 | D6: 0 | E6: 13 | F6: 5 | G6: -2 | H6: 3
A7: South | B7: East | C7: 0 | D7: 8 | E7: 8 | G7: 20 | H7: 20
B8: West | D8: 15 | E8: 15 | F8: 7 | H8: 7
A9: South Total | C9: 0 | D9: 23 | E9: 23 | F9: 7 | G9: 20 | H9: 27
A10: West | B10: East | C10: 4 | E10: 4
B11: Unique
A12: West Total | C12: 4 | E12: 4

Sheet CustomTwo
A1: Revenue | C1: Product | D1: Channel
C2: A | E2: A Sum | F2: A Average | G2: B | I2: B Sum | J2: B Average | K2: C | L2: C Sum | M2: C Average | T2: Grand Total
A3: Region | B3: City | C3: Retail | D3: Web | G3: Retail | H3: Web | K3: Direct | N3: Direct Sum | O3: Direct Average | P3: Retail Sum | Q3: Retail Average | R3: Web Sum | S3: Web Average
A4: North | B4: East | C4: 13 | E4: 13 | F4: 6.5 | H4: -2 | I4: -2 | J4: -2 | P4: 13 | Q4: 6.5 | R4: -2 | S4: -2 | T4: 11
B5: West | D5: 0 | E5: 0 | F5: #DIV/0! | G5: 5 | I5: 5 | J5: 5 | P5: 5 | Q5: 5 | R5: 0 | S5: #DIV/0! | T5: 5
A6: North Sum | C6: 13 | D6: 0 | E6: 13 | G6: 5 | H6: -2 | I6: 3 | P6: 18 | R6: -2 | T6: 16
A7: North Average | C7: 6.5 | D7: #DIV/0! | F7: 6.5 | G7: 5 | H7: -2 | J7: 1.5 | Q7: 6 | S7: -2 | T7: 4
A8: South | B8: East | C8: 0 | D8: 8 | E8: 8 | F8: 8 | H8: 20 | I8: 20 | J8: 20 | P8: 0 | Q8: #DIV/0! | R8: 28 | S8: 14 | T8: 28
B9: West | D9: 15 | E9: 15 | F9: 15 | G9: 7 | I9: 7 | J9: 7 | P9: 7 | Q9: 7 | R9: 15 | S9: 15 | T9: 22
A10: South Sum | C10: 0 | D10: 23 | E10: 23 | G10: 7 | H10: 20 | I10: 27 | P10: 7 | R10: 43 | T10: 50
A11: South Average | C11: #DIV/0! | D11: 11.5 | F11: 11.5 | G11: 7 | H11: 20 | J11: 13.5 | Q11: 7 | S11: 14.333333 | T11: 12.5
A12: West | B12: East | C12: 4 | E12: 4 | F12: 4 | P12: 4 | Q12: 4 | T12: 4
B13: Unique
A14: West Sum | C14: 4 | E14: 4 | P14: 4 | T14: 4
A15: West Average | C15: 4 | F15: 4 | Q15: 4 | T15: 4
B16: East Sum | C16: 17 | D16: 8 | E16: 25 | H16: 18 | I16: 18 | P16: 17 | R16: 26 | T16: 43
B17: East Average | C17: 5.6666667 | D17: 8 | F17: 6.25 | H17: 9 | J17: 9 | Q17: 5.6666667 | S17: 8.6666667 | T17: 7.1666667
B18: Unique Sum
B19: Unique Average
B20: West Sum | D20: 15 | E20: 15 | G20: 12 | I20: 12 | P20: 12 | R20: 15 | T20: 27
B21: West Average | D21: 15 | F21: 15 | G21: 6 | J21: 6 | Q21: 6 | S21: 15 | T21: 9
A22: Grand Total | C22: 17 | D22: 23 | E22: 40 | F22: 8 | G22: 12 | H22: 18 | I22: 30 | J22: 7.5 | P22: 29 | Q22: 5.8 | R22: 41 | S22: 10.25 | T22: 70

Sheet CustomSum
A1: Revenue | C1: Product | D1: Channel
C2: A | E2: A Sum | F2: B | H2: B Sum | I2: C | J2: C Sum | N2: Grand Total
A3: Region | B3: City | C3: Retail | D3: Web | F3: Retail | G3: Web | I3: Direct | K3: Direct Sum | L3: Retail Sum | M3: Web Sum
A4: North | B4: East | C4: 13 | E4: 13 | G4: -2 | H4: -2 | L4: 13 | M4: -2 | N4: 11
B5: West | D5: 0 | E5: 0 | F5: 5 | H5: 5 | L5: 5 | M5: 0 | N5: 5
A6: North Sum | C6: 13 | D6: 0 | E6: 13 | F6: 5 | G6: -2 | H6: 3 | L6: 18 | M6: -2 | N6: 16
A7: South | B7: East | C7: 0 | D7: 8 | E7: 8 | G7: 20 | H7: 20 | L7: 0 | M7: 28 | N7: 28
B8: West | D8: 15 | E8: 15 | F8: 7 | H8: 7 | L8: 7 | M8: 15 | N8: 22
A9: South Sum | C9: 0 | D9: 23 | E9: 23 | F9: 7 | G9: 20 | H9: 27 | L9: 7 | M9: 43 | N9: 50
A10: West | B10: East | C10: 4 | E10: 4 | L10: 4 | N10: 4
B11: Unique
A12: West Sum | C12: 4 | E12: 4 | L12: 4 | N12: 4
B13: East Sum | C13: 17 | D13: 8 | E13: 25 | G13: 18 | H13: 18 | L13: 17 | M13: 26 | N13: 43
B14: Unique Sum
B15: West Sum | D15: 15 | E15: 15 | F15: 12 | H15: 12 | L15: 12 | M15: 15 | N15: 27
A16: Grand Total | C16: 17 | D16: 23 | E16: 40 | F16: 12 | G16: 18 | H16: 30 | L16: 29 | M16: 41 | N16: 70

Sheet NoSubtotals
A1: Revenue | C1: Product | D1: Channel
C2: A | E2: B | G2: C | H2: Grand Total
A3: Region | B3: City | C3: Retail | D3: Web | E3: Retail | F3: Web | G3: Direct
A4: North | B4: East | C4: 13 | F4: -2 | H4: 11
B5: West | D5: 0 | E5: 5 | H5: 5
A6: South | B6: East | C6: 0 | D6: 8 | F6: 20 | H6: 28
B7: West | D7: 15 | E7: 7 | H7: 22
A8: West | B8: East | C8: 4 | H8: 4
B9: Unique
A10: Grand Total | C10: 17 | D10: 23 | E10: 12 | F10: 18 | H10: 70

Sheet OuterRow
D1: Product | E1: Channel
D2: A | F2: A Total | G2: B | I2: B Total | J2: C | K2: C Total | L2: Grand Total
A3: Values | B3: Region | C3: City | D3: Retail | E3: Web | G3: Retail | H3: Web | J3: Direct
A4: Revenue | B4: North | C4: East | D4: 13 | F4: 13 | H4: -2 | I4: -2 | L4: 11
C5: West | E5: 0 | F5: 0 | G5: 5 | I5: 5 | L5: 5
B6: North Total | D6: 13 | E6: 0 | F6: 13 | G6: 5 | H6: -2 | I6: 3 | L6: 16
B7: South | C7: East | D7: 0 | E7: 8 | F7: 8 | H7: 20 | I7: 20 | L7: 28
C8: West | E8: 15 | F8: 15 | G8: 7 | I8: 7 | L8: 22
B9: South Total | D9: 0 | E9: 23 | F9: 23 | G9: 7 | H9: 20 | I9: 27 | L9: 50
B10: West | C10: East | D10: 4 | F10: 4 | L10: 4
C11: Unique
B12: West Total | D12: 4 | F12: 4 | L12: 4
A13: AvgUnits | B13: North | C13: East | D13: 4 | F13: 4 | H13: 1 | I13: 1 | L13: 3
C14: West | E14: 1 | F14: 1 | G14: 1 | I14: 1 | L14: 1
B15: North Total | D15: 4 | E15: 1 | F15: 3 | G15: 1 | H15: 1 | I15: 1 | L15: 2.2
B16: South | C16: East | D16: 2 | E16: 2 | F16: 2 | H16: 3 | I16: 3 | L16: 2.3333333
C17: West | E17: 4 | F17: 4 | G17: 3 | I17: 3 | L17: 3.5
B18: South Total | D18: 2 | E18: 3 | F18: 2.6666667 | G18: 3 | H18: 3 | I18: 3 | L18: 2.8
B19: West | C19: East | D19: 2 | F19: 2 | L19: 2
C20: Unique | J20: 5 | K20: 5 | L20: 5
B21: West Total | D21: 2 | F21: 2 | J21: 5 | K21: 5 | L21: 3.5
A22: Entries | B22: North | C22: East | D22: 2 | F22: 2 | H22: 1 | I22: 1 | L22: 3
C23: West | E23: 1 | F23: 1 | G23: 1 | I23: 1 | L23: 2
B24: North Total | D24: 2 | E24: 1 | F24: 3 | G24: 1 | H24: 1 | I24: 2 | L24: 5
B25: South | C25: East | D25: 1 | E25: 1 | F25: 2 | H25: 1 | I25: 1 | L25: 3
C26: West | E26: 1 | F26: 1 | G26: 1 | I26: 1 | L26: 2
B27: South Total | D27: 1 | E27: 2 | F27: 3 | G27: 1 | H27: 1 | I27: 2 | L27: 5
B28: West | C28: East | D28: 1 | F28: 1 | L28: 1
C29: Unique
B30: West Total | D30: 1 | F30: 1 | L30: 1
A31: Total Revenue | D31: 17 | E31: 23 | F31: 40 | G31: 12 | H31: 18 | I31: 30 | L31: 70
A32: Total AvgUnits | D32: 3 | E32: 2.3333333 | F32: 2.7142857 | G32: 2 | H32: 2 | I32: 2 | J32: 5 | K32: 5 | L32: 2.6666667
A33: Total Entries | D33: 4 | E33: 3 | F33: 7 | G33: 2 | H33: 2 | I33: 4 | L33: 11

Sheet OuterCol
C1: Values | D1: Product | E1: Channel
C2: Revenue | K2: AvgUnits | S2: Entries | AA2: Total Revenue | AB2: Total AvgUnits | AC2: Total Entries
C3: A | E3: A Total | F3: B | H3: B Total | I3: C | J3: C Total | K3: A | M3: A Total | N3: B | P3: B Total | Q3: C | R3: C Total | S3: A | U3: A Total | V3: B | X3: B Total | Y3: C | Z3: C Total
A4: Region | B4: City | C4: Retail | D4: Web | F4: Retail | G4: Web | I4: Direct | K4: Retail | L4: Web | N4: Retail | O4: Web | Q4: Direct | S4: Retail | T4: Web | V4: Retail | W4: Web | Y4: Direct
A5: North | B5: East | C5: 13 | E5: 13 | G5: -2 | H5: -2 | K5: 4 | M5: 4 | O5: 1 | P5: 1 | S5: 2 | U5: 2 | W5: 1 | X5: 1 | AA5: 11 | AB5: 3 | AC5: 3
B6: West | D6: 0 | E6: 0 | F6: 5 | H6: 5 | L6: 1 | M6: 1 | N6: 1 | P6: 1 | T6: 1 | U6: 1 | V6: 1 | X6: 1 | AA6: 5 | AB6: 1 | AC6: 2
A7: North Total | C7: 13 | D7: 0 | E7: 13 | F7: 5 | G7: -2 | H7: 3 | K7: 4 | L7: 1 | M7: 3 | N7: 1 | O7: 1 | P7: 1 | S7: 2 | T7: 1 | U7: 3 | V7: 1 | W7: 1 | X7: 2 | AA7: 16 | AB7: 2.2 | AC7: 5
A8: South | B8: East | C8: 0 | D8: 8 | E8: 8 | G8: 20 | H8: 20 | K8: 2 | L8: 2 | M8: 2 | O8: 3 | P8: 3 | S8: 1 | T8: 1 | U8: 2 | W8: 1 | X8: 1 | AA8: 28 | AB8: 2.3333333 | AC8: 3
B9: West | D9: 15 | E9: 15 | F9: 7 | H9: 7 | L9: 4 | M9: 4 | N9: 3 | P9: 3 | T9: 1 | U9: 1 | V9: 1 | X9: 1 | AA9: 22 | AB9: 3.5 | AC9: 2
A10: South Total | C10: 0 | D10: 23 | E10: 23 | F10: 7 | G10: 20 | H10: 27 | K10: 2 | L10: 3 | M10: 2.6666667 | N10: 3 | O10: 3 | P10: 3 | S10: 1 | T10: 2 | U10: 3 | V10: 1 | W10: 1 | X10: 2 | AA10: 50 | AB10: 2.8 | AC10: 5
A11: West | B11: East | C11: 4 | E11: 4 | K11: 2 | M11: 2 | S11: 1 | U11: 1 | AA11: 4 | AB11: 2 | AC11: 1
B12: Unique | Q12: 5 | R12: 5 | AB12: 5
A13: West Total | C13: 4 | E13: 4 | K13: 2 | M13: 2 | Q13: 5 | R13: 5 | S13: 1 | U13: 1 | AA13: 4 | AB13: 3.5 | AC13: 1
A14: Grand Total | C14: 17 | D14: 23 | E14: 40 | F14: 12 | G14: 18 | H14: 30 | K14: 3 | L14: 2.3333333 | M14: 2.7142857 | N14: 2 | O14: 2 | P14: 2 | Q14: 5 | R14: 5 | S14: 4 | T14: 3 | U14: 7 | V14: 2 | W14: 2 | X14: 4 | AA14: 70 | AB14: 2.6666667 | AC14: 11

Sheet MiddleRow
D1: Product | E1: Channel
D2: A | F2: A Total | G2: B | I2: B Total | J2: C | K2: C Total | L2: Grand Total
A3: Region | B3: Values | C3: City | D3: Retail | E3: Web | G3: Retail | H3: Web | J3: Direct
A4: North | B4: Revenue | C4: East | D4: 13 | F4: 13 | H4: -2 | I4: -2 | L4: 11
C5: West | E5: 0 | F5: 0 | G5: 5 | I5: 5 | L5: 5
B6: AvgUnits | C6: East | D6: 4 | F6: 4 | H6: 1 | I6: 1 | L6: 3
C7: West | E7: 1 | F7: 1 | G7: 1 | I7: 1 | L7: 1
B8: Entries | C8: East | D8: 2 | F8: 2 | H8: 1 | I8: 1 | L8: 3
C9: West | E9: 1 | F9: 1 | G9: 1 | I9: 1 | L9: 2
A10: North Revenue | D10: 13 | E10: 0 | F10: 13 | G10: 5 | H10: -2 | I10: 3 | L10: 16
A11: North AvgUnits | D11: 4 | E11: 1 | F11: 3 | G11: 1 | H11: 1 | I11: 1 | L11: 2.2
A12: North Entries | D12: 2 | E12: 1 | F12: 3 | G12: 1 | H12: 1 | I12: 2 | L12: 5
A13: South | B13: Revenue | C13: East | D13: 0 | E13: 8 | F13: 8 | H13: 20 | I13: 20 | L13: 28
C14: West | E14: 15 | F14: 15 | G14: 7 | I14: 7 | L14: 22
B15: AvgUnits | C15: East | D15: 2 | E15: 2 | F15: 2 | H15: 3 | I15: 3 | L15: 2.3333333
C16: West | E16: 4 | F16: 4 | G16: 3 | I16: 3 | L16: 3.5
B17: Entries | C17: East | D17: 1 | E17: 1 | F17: 2 | H17: 1 | I17: 1 | L17: 3
C18: West | E18: 1 | F18: 1 | G18: 1 | I18: 1 | L18: 2
A19: South Revenue | D19: 0 | E19: 23 | F19: 23 | G19: 7 | H19: 20 | I19: 27 | L19: 50
A20: South AvgUnits | D20: 2 | E20: 3 | F20: 2.6666667 | G20: 3 | H20: 3 | I20: 3 | L20: 2.8
A21: South Entries | D21: 1 | E21: 2 | F21: 3 | G21: 1 | H21: 1 | I21: 2 | L21: 5
A22: West | B22: Revenue | C22: East | D22: 4 | F22: 4 | L22: 4
C23: Unique
B24: AvgUnits | C24: East | D24: 2 | F24: 2 | L24: 2
C25: Unique | J25: 5 | K25: 5 | L25: 5
B26: Entries | C26: East | D26: 1 | F26: 1 | L26: 1
C27: Unique
A28: West Revenue | D28: 4 | F28: 4 | L28: 4
A29: West AvgUnits | D29: 2 | F29: 2 | J29: 5 | K29: 5 | L29: 3.5
A30: West Entries | D30: 1 | F30: 1 | L30: 1
A31: Total Revenue | D31: 17 | E31: 23 | F31: 40 | G31: 12 | H31: 18 | I31: 30 | L31: 70
A32: Total AvgUnits | D32: 3 | E32: 2.3333333 | F32: 2.7142857 | G32: 2 | H32: 2 | I32: 2 | J32: 5 | K32: 5 | L32: 2.6666667
A33: Total Entries | D33: 4 | E33: 3 | F33: 7 | G33: 2 | H33: 2 | I33: 4 | L33: 11

Sheet MiddleCol
C1: Product | D1: Values | E1: Channel
C2: A | I2: A Revenue | J2: A AvgUnits | K2: A Entries | L2: B | R2: B Revenue | S2: B AvgUnits | T2: B Entries | U2: C | X2: C Revenue | Y2: C AvgUnits | Z2: C Entries | AA2: Total Revenue | AB2: Total AvgUnits | AC2: Total Entries
C3: Revenue | E3: AvgUnits | G3: Entries | L3: Revenue | N3: AvgUnits | P3: Entries | U3: Revenue | V3: AvgUnits | W3: Entries
A4: Region | B4: City | C4: Retail | D4: Web | E4: Retail | F4: Web | G4: Retail | H4: Web | L4: Retail | M4: Web | N4: Retail | O4: Web | P4: Retail | Q4: Web | U4: Direct | V4: Direct | W4: Direct
A5: North | B5: East | C5: 13 | E5: 4 | G5: 2 | I5: 13 | J5: 4 | K5: 2 | M5: -2 | O5: 1 | Q5: 1 | R5: -2 | S5: 1 | T5: 1 | AA5: 11 | AB5: 3 | AC5: 3
B6: West | D6: 0 | F6: 1 | H6: 1 | I6: 0 | J6: 1 | K6: 1 | L6: 5 | N6: 1 | P6: 1 | R6: 5 | S6: 1 | T6: 1 | AA6: 5 | AB6: 1 | AC6: 2
A7: North Total | C7: 13 | D7: 0 | E7: 4 | F7: 1 | G7: 2 | H7: 1 | I7: 13 | J7: 3 | K7: 3 | L7: 5 | M7: -2 | N7: 1 | O7: 1 | P7: 1 | Q7: 1 | R7: 3 | S7: 1 | T7: 2 | AA7: 16 | AB7: 2.2 | AC7: 5
A8: South | B8: East | C8: 0 | D8: 8 | E8: 2 | F8: 2 | G8: 1 | H8: 1 | I8: 8 | J8: 2 | K8: 2 | M8: 20 | O8: 3 | Q8: 1 | R8: 20 | S8: 3 | T8: 1 | AA8: 28 | AB8: 2.3333333 | AC8: 3
B9: West | D9: 15 | F9: 4 | H9: 1 | I9: 15 | J9: 4 | K9: 1 | L9: 7 | N9: 3 | P9: 1 | R9: 7 | S9: 3 | T9: 1 | AA9: 22 | AB9: 3.5 | AC9: 2
A10: South Total | C10: 0 | D10: 23 | E10: 2 | F10: 3 | G10: 1 | H10: 2 | I10: 23 | J10: 2.6666667 | K10: 3 | L10: 7 | M10: 20 | N10: 3 | O10: 3 | P10: 1 | Q10: 1 | R10: 27 | S10: 3 | T10: 2 | AA10: 50 | AB10: 2.8 | AC10: 5
A11: West | B11: East | C11: 4 | E11: 2 | G11: 1 | I11: 4 | J11: 2 | K11: 1 | AA11: 4 | AB11: 2 | AC11: 1
B12: Unique | V12: 5 | Y12: 5 | AB12: 5
A13: West Total | C13: 4 | E13: 2 | G13: 1 | I13: 4 | J13: 2 | K13: 1 | V13: 5 | Y13: 5 | AA13: 4 | AB13: 3.5 | AC13: 1
A14: Grand Total | C14: 17 | D14: 23 | E14: 3 | F14: 2.3333333 | G14: 4 | H14: 3 | I14: 40 | J14: 2.7142857 | K14: 7 | L14: 12 | M14: 18 | N14: 2 | O14: 2 | P14: 2 | Q14: 2 | R14: 30 | S14: 2 | T14: 4 | V14: 5 | Y14: 5 | AA14: 70 | AB14: 2.6666667 | AC14: 11

Sheet ManyRow
D1: Product | E1: Channel
D2: A | F2: A Total | G2: B | I2: B Total | J2: C | K2: C Total | L2: Grand Total
A3: Region | B3: City | C3: Values | D3: Retail | E3: Web | G3: Retail | H3: Web | J3: Direct
A4: North | B4: East | C4: Revenue | D4: 13 | F4: 13 | H4: -2 | I4: -2 | L4: 11
C5: AvgUnits | D5: 4 | F5: 4 | H5: 1 | I5: 1 | L5: 3
C6: Entries | D6: 2 | F6: 2 | H6: 1 | I6: 1 | L6: 3
B7: West | C7: Revenue | E7: 0 | F7: 0 | G7: 5 | I7: 5 | L7: 5
C8: AvgUnits | E8: 1 | F8: 1 | G8: 1 | I8: 1 | L8: 1
C9: Entries | E9: 1 | F9: 1 | G9: 1 | I9: 1 | L9: 2
A10: North Revenue | D10: 13 | E10: 0 | F10: 13 | G10: 5 | H10: -2 | I10: 3 | L10: 16
A11: North AvgUnits | D11: 4 | E11: 1 | F11: 3 | G11: 1 | H11: 1 | I11: 1 | L11: 2.2
A12: North Entries | D12: 2 | E12: 1 | F12: 3 | G12: 1 | H12: 1 | I12: 2 | L12: 5
A13: South | B13: East | C13: Revenue | D13: 0 | E13: 8 | F13: 8 | H13: 20 | I13: 20 | L13: 28
C14: AvgUnits | D14: 2 | E14: 2 | F14: 2 | H14: 3 | I14: 3 | L14: 2.3333333
C15: Entries | D15: 1 | E15: 1 | F15: 2 | H15: 1 | I15: 1 | L15: 3
B16: West | C16: Revenue | E16: 15 | F16: 15 | G16: 7 | I16: 7 | L16: 22
C17: AvgUnits | E17: 4 | F17: 4 | G17: 3 | I17: 3 | L17: 3.5
C18: Entries | E18: 1 | F18: 1 | G18: 1 | I18: 1 | L18: 2
A19: South Revenue | D19: 0 | E19: 23 | F19: 23 | G19: 7 | H19: 20 | I19: 27 | L19: 50
A20: South AvgUnits | D20: 2 | E20: 3 | F20: 2.6666667 | G20: 3 | H20: 3 | I20: 3 | L20: 2.8
A21: South Entries | D21: 1 | E21: 2 | F21: 3 | G21: 1 | H21: 1 | I21: 2 | L21: 5
A22: West | B22: East | C22: Revenue | D22: 4 | F22: 4 | L22: 4
C23: AvgUnits | D23: 2 | F23: 2 | L23: 2
C24: Entries | D24: 1 | F24: 1 | L24: 1
B25: Unique | C25: Revenue
C26: AvgUnits | J26: 5 | K26: 5 | L26: 5
C27: Entries
A28: West Revenue | D28: 4 | F28: 4 | L28: 4
A29: West AvgUnits | D29: 2 | F29: 2 | J29: 5 | K29: 5 | L29: 3.5
A30: West Entries | D30: 1 | F30: 1 | L30: 1
A31: Total Revenue | D31: 17 | E31: 23 | F31: 40 | G31: 12 | H31: 18 | I31: 30 | L31: 70
A32: Total AvgUnits | D32: 3 | E32: 2.3333333 | F32: 2.7142857 | G32: 2 | H32: 2 | I32: 2 | J32: 5 | K32: 5 | L32: 2.6666667
A33: Total Entries | D33: 4 | E33: 3 | F33: 7 | G33: 2 | H33: 2 | I33: 4 | L33: 11

Sheet ManyCol
C1: Product | D1: Channel | E1: Values
C2: A | I2: A Revenue | J2: A AvgUnits | K2: A Entries | L2: B | R2: B Revenue | S2: B AvgUnits | T2: B Entries | U2: C | X2: C Revenue | Y2: C AvgUnits | Z2: C Entries | AA2: Total Revenue | AB2: Total AvgUnits | AC2: Total Entries
C3: Retail | F3: Web | L3: Retail | O3: Web | U3: Direct
A4: Region | B4: City | C4: Revenue | D4: AvgUnits | E4: Entries | F4: Revenue | G4: AvgUnits | H4: Entries | L4: Revenue | M4: AvgUnits | N4: Entries | O4: Revenue | P4: AvgUnits | Q4: Entries | U4: Revenue | V4: AvgUnits | W4: Entries
A5: North | B5: East | C5: 13 | D5: 4 | E5: 2 | I5: 13 | J5: 4 | K5: 2 | O5: -2 | P5: 1 | Q5: 1 | R5: -2 | S5: 1 | T5: 1 | AA5: 11 | AB5: 3 | AC5: 3
B6: West | F6: 0 | G6: 1 | H6: 1 | I6: 0 | J6: 1 | K6: 1 | L6: 5 | M6: 1 | N6: 1 | R6: 5 | S6: 1 | T6: 1 | AA6: 5 | AB6: 1 | AC6: 2
A7: North Total | C7: 13 | D7: 4 | E7: 2 | F7: 0 | G7: 1 | H7: 1 | I7: 13 | J7: 3 | K7: 3 | L7: 5 | M7: 1 | N7: 1 | O7: -2 | P7: 1 | Q7: 1 | R7: 3 | S7: 1 | T7: 2 | AA7: 16 | AB7: 2.2 | AC7: 5
A8: South | B8: East | C8: 0 | D8: 2 | E8: 1 | F8: 8 | G8: 2 | H8: 1 | I8: 8 | J8: 2 | K8: 2 | O8: 20 | P8: 3 | Q8: 1 | R8: 20 | S8: 3 | T8: 1 | AA8: 28 | AB8: 2.3333333 | AC8: 3
B9: West | F9: 15 | G9: 4 | H9: 1 | I9: 15 | J9: 4 | K9: 1 | L9: 7 | M9: 3 | N9: 1 | R9: 7 | S9: 3 | T9: 1 | AA9: 22 | AB9: 3.5 | AC9: 2
A10: South Total | C10: 0 | D10: 2 | E10: 1 | F10: 23 | G10: 3 | H10: 2 | I10: 23 | J10: 2.6666667 | K10: 3 | L10: 7 | M10: 3 | N10: 1 | O10: 20 | P10: 3 | Q10: 1 | R10: 27 | S10: 3 | T10: 2 | AA10: 50 | AB10: 2.8 | AC10: 5
A11: West | B11: East | C11: 4 | D11: 2 | E11: 1 | I11: 4 | J11: 2 | K11: 1 | AA11: 4 | AB11: 2 | AC11: 1
B12: Unique | V12: 5 | Y12: 5 | AB12: 5
A13: West Total | C13: 4 | D13: 2 | E13: 1 | I13: 4 | J13: 2 | K13: 1 | V13: 5 | Y13: 5 | AA13: 4 | AB13: 3.5 | AC13: 1
A14: Grand Total | C14: 17 | D14: 3 | E14: 4 | F14: 23 | G14: 2.3333333 | H14: 3 | I14: 40 | J14: 2.7142857 | K14: 7 | L14: 12 | M14: 2 | N14: 2 | O14: 18 | P14: 2 | Q14: 2 | R14: 30 | S14: 2 | T14: 4 | V14: 5 | Y14: 5 | AA14: 70 | AB14: 2.6666667 | AC14: 11

Sheet Col3
B1: Product | C1: Channel | D1: Region
B2: A | I2: A Total | J2: B | P2: B Total | Q2: C | S2: C Total | T2: Grand Total
B3: Retail | E3: Retail Total | F3: Web | H3: Web Total | J3: Retail | L3: Retail Total | M3: Web | O3: Web Total | Q3: Direct | R3: Direct Total
B4: North | C4: South | D4: West | F4: North | G4: South | J4: North | K4: South | M4: North | N4: South | Q4: West
A5: Revenue | B5: 13 | C5: 0 | D5: 4 | E5: 17 | F5: 0 | G5: 23 | H5: 23 | I5: 40 | J5: 5 | K5: 7 | L5: 12 | M5: -2 | N5: 20 | O5: 18 | P5: 30 | T5: 70

Sheet Row3
A1: Region | B1: City | C1: Product | D1: Revenue
A2: North | B2: East | C2: A | D2: 13
C3: B | D3: -2
B4: East Total | D4: 11
B5: West | C5: A | D5: 0
C6: B | D6: 5
B7: West Total | D7: 5
A8: North Total | D8: 16
A9: South | B9: East | C9: A | D9: 8
C10: B | D10: 20
B11: East Total | D11: 28
B12: West | C12: A | D12: 15
C13: B | D13: 7
B14: West Total | D14: 22
A15: South Total | D15: 50
A16: West | B16: East | C16: A | D16: 4
B17: East Total | D17: 4
B18: Unique | C18: C
B19: Unique Total
A20: West Total | D20: 4
A21: Grand Total | D21: 70

Sheet Both2
A1: Revenue | C1: Product | D1: Channel
C2: A | E2: A Total | F2: B | H2: B Total | I2: C | J2: C Total | K2: Grand Total
A3: Region | B3: City | C3: Retail | D3: Web | F3: Retail | G3: Web | I3: Direct
A4: North | B4: East | C4: 13 | E4: 13 | G4: -2 | H4: -2 | K4: 11
B5: West | D5: 0 | E5: 0 | F5: 5 | H5: 5 | K5: 5
A6: North Total | C6: 13 | D6: 0 | E6: 13 | F6: 5 | G6: -2 | H6: 3 | K6: 16
A7: South | B7: East | C7: 0 | D7: 8 | E7: 8 | G7: 20 | H7: 20 | K7: 28
B8: West | D8: 15 | E8: 15 | F8: 7 | H8: 7 | K8: 22
A9: South Total | C9: 0 | D9: 23 | E9: 23 | F9: 7 | G9: 20 | H9: 27 | K9: 50
A10: West | B10: East | C10: 4 | E10: 4 | K10: 4
B11: Unique
A12: West Total | C12: 4 | E12: 4 | K12: 4
A13: Grand Total | C13: 17 | D13: 23 | E13: 40 | F13: 12 | G13: 18 | H13: 30 | K13: 70

Sheet Col2
B1: Product | C1: Channel
B2: A | D2: A Total | E2: B | G2: B Total | H2: C | I2: C Total | J2: Grand Total
B3: Retail | C3: Web | E3: Retail | F3: Web | H3: Direct
A4: Revenue | B4: 17 | C4: 23 | D4: 40 | E4: 12 | F4: 18 | G4: 30 | J4: 70

Sheet Row2
A1: Region | B1: City | C1: Revenue
A2: North | B2: East | C2: 11
B3: West | C3: 5
A4: North Total | C4: 16
A5: South | B5: East | C5: 28
B6: West | C6: 22
A7: South Total | C7: 50
A8: West | B8: East | C8: 4
B9: Unique
A10: West Total | C10: 4
A11: Grand Total | C11: 70

Sheet Lookups
A1: Row2 | B1: =GETPIVOTDATA("Revenue",'Row2'!A1) -> 70
A2: Row2 | B2: =GETPIVOTDATA("Revenue",'Row2'!A1,"Region","North") -> 16
A3: Row2 | B3: =GETPIVOTDATA("Revenue",'Row2'!A1,"City","East") -> #REF!
A4: Row2 | B4: =GETPIVOTDATA("Revenue",'Row2'!A1,"Region","North","City","East") -> 11
A5: Row2 | B5: =GETPIVOTDATA("Revenue",'Row2'!A1,"Product","A") -> #REF!
A6: Row2 | B6: =GETPIVOTDATA("Revenue",'Row2'!A1,"Region","North","Product","A") -> #REF!
A7: Row2 | B7: =GETPIVOTDATA("Revenue",'Row2'!A1,"City","East","Product","A") -> #REF!
A8: Row2 | B8: =GETPIVOTDATA("Revenue",'Row2'!A1,"Region","North","City","East","Product","A") -> #REF!
A9: Row2 | B9: =GETPIVOTDATA("Revenue",'Row2'!A1,"Channel","Retail") -> #REF!
A10: Row2 | B10: =GETPIVOTDATA("Revenue",'Row2'!A1,"Region","North","Channel","Retail") -> #REF!
A11: Row2 | B11: =GETPIVOTDATA("Revenue",'Row2'!A1,"City","East","Channel","Retail") -> #REF!
A12: Row2 | B12: =GETPIVOTDATA("Revenue",'Row2'!A1,"Region","North","City","East","Channel","Retail") -> #REF!
A13: Row2 | B13: =GETPIVOTDATA("Revenue",'Row2'!A1,"Product","A","Channel","Retail") -> #REF!
A14: Row2 | B14: =GETPIVOTDATA("Revenue",'Row2'!A1,"Region","North","Product","A","Channel","Retail") -> #REF!
A15: Row2 | B15: =GETPIVOTDATA("Revenue",'Row2'!A1,"City","East","Product","A","Channel","Retail") -> #REF!
A16: Row2 | B16: =GETPIVOTDATA("Revenue",'Row2'!A1,"Region","North","City","East","Product","A","Channel","Retail") -> #REF!
A17: Row2 | B17: =GETPIVOTDATA("Revenue",'Row2'!A1,"City","Unique") -> 0
A18: Row2 | B18: =GETPIVOTDATA("Revenue",'Row2'!A1,"Product","C") -> #REF!
A19: Row2 | B19: =GETPIVOTDATA("Revenue",'Row2'!A1,"Channel","Direct") -> #REF!
A20: Row2 | B20: =GETPIVOTDATA("Revenue",'Row2'!A1,"Region","North","City","missing") -> #REF!
A21: Row2 | B21: =GETPIVOTDATA("Revenue",'Row2'!A1,"Region","West","City","Unique","Product","C","Channel","Direct") -> #REF!
A22: Col2 | B22: =GETPIVOTDATA("Revenue",'Col2'!A1) -> 70
A23: Col2 | B23: =GETPIVOTDATA("Revenue",'Col2'!A1,"Region","North") -> #REF!
A24: Col2 | B24: =GETPIVOTDATA("Revenue",'Col2'!A1,"City","East") -> #REF!
A25: Col2 | B25: =GETPIVOTDATA("Revenue",'Col2'!A1,"Region","North","City","East") -> #REF!
A26: Col2 | B26: =GETPIVOTDATA("Revenue",'Col2'!A1,"Product","A") -> 40
A27: Col2 | B27: =GETPIVOTDATA("Revenue",'Col2'!A1,"Region","North","Product","A") -> #REF!
A28: Col2 | B28: =GETPIVOTDATA("Revenue",'Col2'!A1,"City","East","Product","A") -> #REF!
A29: Col2 | B29: =GETPIVOTDATA("Revenue",'Col2'!A1,"Region","North","City","East","Product","A") -> #REF!
A30: Col2 | B30: =GETPIVOTDATA("Revenue",'Col2'!A1,"Channel","Retail") -> #REF!
A31: Col2 | B31: =GETPIVOTDATA("Revenue",'Col2'!A1,"Region","North","Channel","Retail") -> #REF!
A32: Col2 | B32: =GETPIVOTDATA("Revenue",'Col2'!A1,"City","East","Channel","Retail") -> #REF!
A33: Col2 | B33: =GETPIVOTDATA("Revenue",'Col2'!A1,"Region","North","City","East","Channel","Retail") -> #REF!
A34: Col2 | B34: =GETPIVOTDATA("Revenue",'Col2'!A1,"Product","A","Channel","Retail") -> 17
A35: Col2 | B35: =GETPIVOTDATA("Revenue",'Col2'!A1,"Region","North","Product","A","Channel","Retail") -> #REF!
A36: Col2 | B36: =GETPIVOTDATA("Revenue",'Col2'!A1,"City","East","Product","A","Channel","Retail") -> #REF!
A37: Col2 | B37: =GETPIVOTDATA("Revenue",'Col2'!A1,"Region","North","City","East","Product","A","Channel","Retail") -> #REF!
A38: Col2 | B38: =GETPIVOTDATA("Revenue",'Col2'!A1,"City","Unique") -> #REF!
A39: Col2 | B39: =GETPIVOTDATA("Revenue",'Col2'!A1,"Product","C") -> 0
A40: Col2 | B40: =GETPIVOTDATA("Revenue",'Col2'!A1,"Channel","Direct") -> 0
...

Sheet Source
A1: Region | B1: City | C1: Product | D1: Channel | E1: Amount | F1: Units
A2: North | B2: East | C2: A | D2: Retail | E2: 10 | F2: 2
A3: South | B3: East | C3: B | D3: Web | E3: 20 | F3: 3
A4: North | B4: West | C4: B | D4: Retail | E4: 5 | F4: 1
A5: South | B5: West | C5: A | D5: Web | E5: 15 | F5: 4
A6: North | B6: East | C6: B | D6: Web | E6: -2 | F6: 1
A7: West | B7: Unique | C7: C | D7: Direct | F7: 5
A8: South | B8: East | C8: A | D8: Retail | E8: pending | F8: 2
A9: North | B9: West | C9: A | D9: Web | E9: TRUE | F9: 1
A10: South | B10: East | C10: A | D10: Web | E10: 8 | F10: 2
A11: North | B11: East | C11: A | D11: Retail | E11: 3 | F11: 6
A12: West | B12: East | C12: A | D12: Retail | E12: 4 | F12: 2
A13: South | B13: West | C13: B | D13: Retail | E13: 7 | F13: 3
