Workbook

Sheet ColColOuter
A1: Values | B1: Product
A2: Revenue | C2: AvgUnits | E2: Entries | G2: Total Revenue | H2: Total AvgUnits | I2: Total Entries
A3: A | B3: B | C3: A | D3: B | E3: A | F3: B
A4: 13 | B4: 35 | C4: 1.5 | D4: 3.25 | E4: 4 | F4: 3 | G4: 48 | H4: 2.375 | I4: 7

Sheet RowRowOuter
A1: Values | B1: Region
A2: Revenue | B2: North | C2: 28
B3: South | C3: 20
B4: West
A5: AvgUnits | B5: North | C5: 1.75
B6: South | C6: 2.3333333
B7: West | C7: 5
A8: Entries | B8: North | C8: 4
B9: South | C9: 3
B10: West
A11: Total Revenue | C11: 48
A12: Total AvgUnits | C12: 2.375
A13: Total Entries | C13: 7

Sheet BothRowOuter
C1: Product
A2: Values | B2: Region | C2: A | D2: B | E2: Grand Total
A3: Revenue | B3: North | C3: 8 | D3: 20 | E3: 28
B4: South | C4: 5 | D4: 15 | E4: 20
B5: West
A6: AvgUnits | B6: North | C6: 1.5 | D6: 2 | E6: 1.75
B7: South | C7: 1.5 | D7: 4 | E7: 2.3333333
B8: West | D8: 5 | E8: 5
A9: Entries | B9: North | C9: 2 | D9: 2 | E9: 4
B10: South | C10: 2 | D10: 1 | E10: 3
B11: West
A12: Total Revenue | C12: 13 | D12: 35 | E12: 48
A13: Total AvgUnits | C13: 1.5 | D13: 3.25 | E13: 2.375
A14: Total Entries | C14: 4 | D14: 3 | E14: 7

Sheet BothColOuter
B1: Values | C1: Product
B2: Revenue | D2: AvgUnits | F2: Entries | H2: Total Revenue | I2: Total AvgUnits | J2: Total Entries
A3: Region | B3: A | C3: B | D3: A | E3: B | F3: A | G3: B
A4: North | B4: 8 | C4: 20 | D4: 1.5 | E4: 2 | F4: 2 | G4: 2 | H4: 28 | I4: 1.75 | J4: 4
A5: South | B5: 5 | C5: 15 | D5: 1.5 | E5: 4 | F5: 2 | G5: 1 | H5: 20 | I5: 2.3333333 | J5: 3
A6: West | E6: 5 | I6: 5
A7: Grand Total | B7: 13 | C7: 35 | D7: 1.5 | E7: 3.25 | F7: 4 | G7: 3 | H7: 48 | I7: 2.375 | J7: 7

Sheet ScalarRow
A1: Values
A2: Revenue | B2: 48
A3: AvgUnits | B3: 2.375
A4: Entries | B4: 7

Sheet ScalarCol
A1: Revenue | B1: AvgUnits | C1: Entries
A2: 48 | B2: 2.375 | C2: 7

Sheet ColRow
B1: Product
A2: Values | B2: A | C2: B | D2: Grand Total
A3: Revenue | B3: 13 | C3: 35 | D3: 48
A4: AvgUnits | B4: 1.5 | C4: 3.25 | D4: 2.375
A5: Entries | B5: 4 | C5: 3 | D5: 7

Sheet ColCol
A1: Product | B1: Values
A2: A | D2: B | G2: Total Revenue | H2: Total AvgUnits | I2: Total Entries
A3: Revenue | B3: AvgUnits | C3: Entries | D3: Revenue | E3: AvgUnits | F3: Entries
A4: 13 | B4: 1.5 | C4: 4 | D4: 35 | E4: 3.25 | F4: 3 | G4: 48 | H4: 2.375 | I4: 7

Sheet RowRow
A1: Region | B1: Values
A2: North | B2: Revenue | C2: 28
B3: AvgUnits | C3: 1.75
B4: Entries | C4: 4
A5: South | B5: Revenue | C5: 20
B6: AvgUnits | C6: 2.3333333
B7: Entries | C7: 3
A8: West | B8: Revenue
B9: AvgUnits | C9: 5
B10: Entries
A11: Total Revenue | C11: 48
A12: Total AvgUnits | C12: 2.375
A13: Total Entries | C13: 7

Sheet RowCol
A1: Region | B1: Revenue | C1: AvgUnits | D1: Entries
A2: North | B2: 28 | C2: 1.75 | D2: 4
A3: South | B3: 20 | C3: 2.3333333 | D3: 3
A4: West | C4: 5
A5: Grand Total | B5: 48 | C5: 2.375 | D5: 7

Sheet BothRow
C1: Product
A2: Region | B2: Values | C2: A | D2: B | E2: Grand Total
A3: North | B3: Revenue | C3: 8 | D3: 20 | E3: 28
B4: AvgUnits | C4: 1.5 | D4: 2 | E4: 1.75
B5: Entries | C5: 2 | D5: 2 | E5: 4
A6: South | B6: Revenue | C6: 5 | D6: 15 | E6: 20
B7: AvgUnits | C7: 1.5 | D7: 4 | E7: 2.3333333
B8: Entries | C8: 2 | D8: 1 | E8: 3
A9: West | B9: Revenue
B10: AvgUnits | D10: 5 | E10: 5
B11: Entries
A12: Total Revenue | C12: 13 | D12: 35 | E12: 48
A13: Total AvgUnits | C13: 1.5 | D13: 3.25 | E13: 2.375
A14: Total Entries | C14: 4 | D14: 3 | E14: 7

Sheet BothCol
B1: Product | C1: Values
B2: A | E2: B | H2: Total Revenue | I2: Total AvgUnits | J2: Total Entries
A3: Region | B3: Revenue | C3: AvgUnits | D3: Entries | E3: Revenue | F3: AvgUnits | G3: Entries
A4: North | B4: 8 | C4: 1.5 | D4: 2 | E4: 20 | F4: 2 | G4: 2 | H4: 28 | I4: 1.75 | J4: 4
A5: South | B5: 5 | C5: 1.5 | D5: 2 | E5: 15 | F5: 4 | G5: 1 | H5: 20 | I5: 2.3333333 | J5: 3
A6: West | F6: 5 | I6: 5
A7: Grand Total | B7: 13 | C7: 1.5 | D7: 4 | E7: 35 | F7: 3.25 | G7: 3 | H7: 48 | I7: 2.375 | J7: 7

Sheet Lookups
A1: BothCol | B1: =GETPIVOTDATA("Revenue",BothCol!A1) -> 48
A2: BothCol | B2: =GETPIVOTDATA("Revenue",BothCol!A1,"Region","North") -> 28
A3: BothCol | B3: =GETPIVOTDATA("Revenue",BothCol!A1,"Region","South") -> 20
A4: BothCol | B4: =GETPIVOTDATA("Revenue",BothCol!A1,"Region","West") -> 0
A5: BothCol | B5: =GETPIVOTDATA("Revenue",BothCol!A1,"Product","A") -> 13
A6: BothCol | B6: =GETPIVOTDATA("Revenue",BothCol!A1,"Product","B") -> 35
A7: BothCol | B7: =GETPIVOTDATA("Revenue",BothCol!A1,"Region","North","Product","A") -> 8
A8: BothCol | B8: =GETPIVOTDATA("Revenue",BothCol!A1,"Region","South","Product","B") -> 15
A9: BothCol | B9: =GETPIVOTDATA("Revenue",BothCol!A1,"Region","missing") -> #REF!
A10: BothCol | B10: =GETPIVOTDATA("AvgUnits",BothCol!A1) -> 2.375
A11: BothCol | B11: =GETPIVOTDATA("AvgUnits",BothCol!A1,"Region","North") -> 1.75
A12: BothCol | B12: =GETPIVOTDATA("AvgUnits",BothCol!A1,"Region","South") -> 2.3333333
A13: BothCol | B13: =GETPIVOTDATA("AvgUnits",BothCol!A1,"Region","West") -> 5
A14: BothCol | B14: =GETPIVOTDATA("AvgUnits",BothCol!A1,"Product","A") -> 1.5
A15: BothCol | B15: =GETPIVOTDATA("AvgUnits",BothCol!A1,"Product","B") -> 3.25
A16: BothCol | B16: =GETPIVOTDATA("AvgUnits",BothCol!A1,"Region","North","Product","A") -> 1.5
A17: BothCol | B17: =GETPIVOTDATA("AvgUnits",BothCol!A1,"Region","South","Product","B") -> 4
A18: BothCol | B18: =GETPIVOTDATA("AvgUnits",BothCol!A1,"Region","missing") -> #REF!
A19: BothCol | B19: =GETPIVOTDATA("Entries",BothCol!A1) -> 7
A20: BothCol | B20: =GETPIVOTDATA("Entries",BothCol!A1,"Region","North") -> 4
A21: BothCol | B21: =GETPIVOTDATA("Entries",BothCol!A1,"Region","South") -> 3
A22: BothCol | B22: =GETPIVOTDATA("Entries",BothCol!A1,"Region","West") -> 0
A23: BothCol | B23: =GETPIVOTDATA("Entries",BothCol!A1,"Product","A") -> 4
A24: BothCol | B24: =GETPIVOTDATA("Entries",BothCol!A1,"Product","B") -> 3
A25: BothCol | B25: =GETPIVOTDATA("Entries",BothCol!A1,"Region","North","Product","A") -> 2
A26: BothCol | B26: =GETPIVOTDATA("Entries",BothCol!A1,"Region","South","Product","B") -> 1
A27: BothCol | B27: =GETPIVOTDATA("Entries",BothCol!A1,"Region","missing") -> #REF!
A28: BothRow | B28: =GETPIVOTDATA("Revenue",BothRow!A1) -> 48
A29: BothRow | B29: =GETPIVOTDATA("Revenue",BothRow!A1,"Region","North") -> 28
A30: BothRow | B30: =GETPIVOTDATA("Revenue",BothRow!A1,"Region","South") -> 20
A31: BothRow | B31: =GETPIVOTDATA("Revenue",BothRow!A1,"Region","West") -> 0
A32: BothRow | B32: =GETPIVOTDATA("Revenue",BothRow!A1,"Product","A") -> 13
A33: BothRow | B33: =GETPIVOTDATA("Revenue",BothRow!A1,"Product","B") -> 35
A34: BothRow | B34: =GETPIVOTDATA("Revenue",BothRow!A1,"Region","North","Product","A") -> 8
A35: BothRow | B35: =GETPIVOTDATA("Revenue",BothRow!A1,"Region","South","Product","B") -> 15
A36: BothRow | B36: =GETPIVOTDATA("Revenue",BothRow!A1,"Region","missing") -> #REF!
A37: BothRow | B37: =GETPIVOTDATA("AvgUnits",BothRow!A1) -> 2.375
A38: BothRow | B38: =GETPIVOTDATA("AvgUnits",BothRow!A1,"Region","North") -> 1.75
A39: BothRow | B39: =GETPIVOTDATA("AvgUnits",BothRow!A1,"Region","South") -> 2.3333333
A40: BothRow | B40: =GETPIVOTDATA("AvgUnits",BothRow!A1,"Region","West") -> 5
...

Sheet Source
A1: Region | B1: Product | C1: Amount | D1: Units
A2: North | B2: A | C2: 10 | D2: 2
A3: North | B3: B | C3: 20 | D3: 3
A4: South | B4: A | C4: 5 | D4: 1
A5: South | B5: B | C5: 15 | D5: 4
A6: North | B6: A | C6: -2 | D6: 1
A7: West | B7: B | D7: 5
A8: South | B8: A | C8: pending | D8: 2
A9: North | B9: B | C9: TRUE | D9: 1
