Workbook

Sheet MixedNested
A1: Group | B1: MixedKey | C1: Revenue
A2: North | B2: 0 | C2: 10
B3: 1 | C3: 20
B4: 59 | C4: 30
B5: 60 | C5: 40
B6: 60.5 | C6: 50
B7: 43830 | C7: 60
B8: 43830.5 | C8: 70
A9: North Total | C9: 280
A10: South | B10: 42 | C10: 60
B11: 43830 | C11: 120
B12: text | C12: 70
B13: TRUE | C13: 80
B14: #DIV/0! | C14: 100
B15: (blank) | C15: 90
A16: South Total | C16: 520
A17: West | B17: #DIV/0! | C17: 110
A18: West Total | C18: 110
A19: Grand Total | C19: 910

Sheet MixedCol
B1: MixedKey
B2: 42 | C2: 43830 | D2: #DIV/0! | E2: text | F2: TRUE | G2: #DIV/0! | H2: 0 | I2: 1 | J2: 59 | K2: 60 | L2: 60.5 | M2: 43830 | N2: 43830.5 | O2: (blank) | P2: Grand Total
A3: Revenue | B3: 60 | C3: 120 | D3: 110 | E3: 70 | F3: 80 | G3: 100 | H3: 10 | I3: 20 | J3: 30 | K3: 40 | L3: 50 | M3: 60 | N3: 70 | O3: 90 | P3: 910

Sheet MixedRow
A1: MixedKey | B1: Revenue
A2: 42 | B2: 60
A3: 43830 | B3: 120
A4: #DIV/0! | B4: 110
A5: text | B5: 70
A6: TRUE | B6: 80
A7: #DIV/0! | B7: 100
A8: 0 | B8: 10
A9: 1 | B9: 20
A10: 59 | B10: 30
A11: 60 | B11: 40
A12: 60.5 | B12: 50
A13: 43830 | B13: 60
A14: 43830.5 | B14: 70
A15: (blank) | B15: 90
A16: Grand Total | B16: 910

Sheet DatesDeepCols
B1: DateKey | C1: Group | D1: Child
B2: 0 | D2: 00:00:00 Total | E2: 1 | G2: 2.01.1904 Total | H2: 59 | J2: 29.02.1904 Total | K2: 60 | M2: 1.03.1904 Total | N2: 60.5 | P2: 1.03.1904 12:00 Total | Q2: 43830 | X2: 1.01.2024 Total | Y2: 43830.5 | AA2: 1.01.2024 12:00 Total | AB2: (blank) | AD2: (blank) Total | AE2: Grand Total
B3: North | C3: North Total | E3: North | F3: North Total | H3: North | I3: North Total | K3: North | L3: North Total | N3: North | O3: North Total | Q3: North | R3: North Total | S3: South | U3: South Total | V3: West | W3: West Total | Y3: North | Z3: North Total | AB3: South | AC3: South Total
B4: Child1 | E4: Child0 | H4: Child1 | K4: Child0 | N4: Child1 | Q4: Child0 | S4: Child0 | T4: Child1 | V4: Child0 | Y4: Child1 | AB4: Child0
A5: Revenue | B5: 10 | C5: 10 | D5: 10 | E5: 20 | F5: 20 | G5: 20 | H5: 30 | I5: 30 | J5: 30 | K5: 40 | L5: 40 | M5: 40 | N5: 50 | O5: 50 | P5: 50 | Q5: 60 | R5: 60 | S5: 130 | T5: 300 | U5: 430 | V5: 110 | W5: 110 | X5: 600 | Y5: 70 | Z5: 70 | AA5: 70 | AB5: 90 | AC5: 90 | AD5: 90 | AE5: 910

Sheet DatesDeepRows
A1: DateKey | B1: Group | C1: Child | D1: Revenue
A2: 0 | B2: North | C2: Child1 | D2: 10
B3: North Total | D3: 10
A4: 00:00:00 Total | D4: 10
A5: 1 | B5: North | C5: Child0 | D5: 20
B6: North Total | D6: 20
A7: 2.01.1904 Total | D7: 20
A8: 59 | B8: North | C8: Child1 | D8: 30
B9: North Total | D9: 30
A10: 29.02.1904 Total | D10: 30
A11: 60 | B11: North | C11: Child0 | D11: 40
B12: North Total | D12: 40
A13: 1.03.1904 Total | D13: 40
A14: 60.5 | B14: North | C14: Child1 | D14: 50
B15: North Total | D15: 50
A16: 1.03.1904 12:00 Total | D16: 50
A17: 43830 | B17: North | C17: Child0 | D17: 60
B18: North Total | D18: 60
B19: South | C19: Child0 | D19: 130
C20: Child1 | D20: 300
B21: South Total | D21: 430
B22: West | C22: Child0 | D22: 110
B23: West Total | D23: 110
A24: 1.01.2024 Total | D24: 600
A25: 43830.5 | B25: North | C25: Child1 | D25: 70
B26: North Total | D26: 70
A27: 1.01.2024 12:00 Total | D27: 70
A28: (blank) | B28: South | C28: Child0 | D28: 90
B29: South Total | D29: 90
A30: (blank) Total | D30: 90
A31: Grand Total | D31: 910

Sheet DatesOuterCols
B1: DateKey | C1: Group
B2: 0 | C2: 00:00:00 Total | D2: 1 | E2: 2.01.1904 Total | F2: 59 | G2: 29.02.1904 Total | H2: 60 | I2: 1.03.1904 Total | J2: 60.5 | K2: 1.03.1904 12:00 Total | L2: 43830 | O2: 1.01.2024 Total | P2: 43830.5 | Q2: 1.01.2024 12:00 Total | R2: (blank) | S2: (blank) Total | T2: Grand Total
B3: North | D3: North | F3: North | H3: North | J3: North | L3: North | M3: South | N3: West | P3: North | R3: South
A4: Revenue | B4: 10 | C4: 10 | D4: 20 | E4: 20 | F4: 30 | G4: 30 | H4: 40 | I4: 40 | J4: 50 | K4: 50 | L4: 60 | M4: 430 | N4: 110 | O4: 600 | P4: 70 | Q4: 70 | R4: 90 | S4: 90 | T4: 910

Sheet DatesOuterRows
A1: DateKey | B1: Group | C1: Revenue
A2: 0 | B2: North | C2: 10
A3: 00:00:00 Total | C3: 10
A4: 1 | B4: North | C4: 20
A5: 2.01.1904 Total | C5: 20
A6: 59 | B6: North | C6: 30
A7: 29.02.1904 Total | C7: 30
A8: 60 | B8: North | C8: 40
A9: 1.03.1904 Total | C9: 40
A10: 60.5 | B10: North | C10: 50
A11: 1.03.1904 12:00 Total | C11: 50
A12: 43830 | B12: North | C12: 60
B13: South | C13: 430
B14: West | C14: 110
A15: 1.01.2024 Total | C15: 600
A16: 43830.5 | B16: North | C16: 70
A17: 1.01.2024 12:00 Total | C17: 70
A18: (blank) | B18: South | C18: 90
A19: (blank) Total | C19: 90
A20: Grand Total | C20: 910

Sheet DatesNested
A1: Group | B1: DateKey | C1: Revenue
A2: North | B2: 0 | C2: 10
B3: 1 | C3: 20
B4: 59 | C4: 30
B5: 60 | C5: 40
B6: 60.5 | C6: 50
B7: 43830 | C7: 60
B8: 43830.5 | C8: 70
A9: North Total | C9: 280
A10: South | B10: 43830 | C10: 430
B11: (blank) | C11: 90
A12: South Total | C12: 520
A13: West | B13: 43830 | C13: 110
A14: West Total | C14: 110
A15: Grand Total | C15: 910

Sheet DatesCol
B1: DateKey
B2: 0 | C2: 1 | D2: 59 | E2: 60 | F2: 60.5 | G2: 43830 | H2: 43830.5 | I2: (blank) | J2: Grand Total
A3: Revenue | B3: 10 | C3: 20 | D3: 30 | E3: 40 | F3: 50 | G3: 600 | H3: 70 | I3: 90 | J3: 910

Sheet DatesRow
A1: DateKey | B1: Revenue
A2: 0 | B2: 10
A3: 1 | B3: 20
A4: 59 | B4: 30
A5: 60 | B5: 40
A6: 60.5 | B6: 50
A7: 43830 | B7: 600
A8: 43830.5 | B8: 70
A9: (blank) | B9: 90
A10: Grand Total | B10: 910

Sheet Lookups
A1: DatesRow | B1: =GETPIVOTDATA("Revenue",DatesRow!A1) -> 910
A2: DatesRow | B2: =GETPIVOTDATA("Revenue",DatesRow!A1,"DateKey",0) -> 10
A3: DatesRow | B3: =GETPIVOTDATA("Revenue",DatesRow!A1,"DateKey",1) -> 20
A4: DatesRow | B4: =GETPIVOTDATA("Revenue",DatesRow!A1,"DateKey",59) -> 30
A5: DatesRow | B5: =GETPIVOTDATA("Revenue",DatesRow!A1,"DateKey",60) -> 40
A6: DatesRow | B6: =GETPIVOTDATA("Revenue",DatesRow!A1,"DateKey",60.5) -> 50
A7: DatesRow | B7: =GETPIVOTDATA("Revenue",DatesRow!A1,"DateKey",43830) -> 600
A8: DatesRow | B8: =GETPIVOTDATA("Revenue",DatesRow!A1,"DateKey",43830.5) -> 70
A9: DatesRow | B9: =GETPIVOTDATA("Revenue",DatesRow!A1,"DateKey","(blank)") -> 90
A10: DatesCol | B10: =GETPIVOTDATA("Revenue",DatesCol!A1) -> 910
A11: DatesCol | B11: =GETPIVOTDATA("Revenue",DatesCol!A1,"DateKey",0) -> 10
A12: DatesCol | B12: =GETPIVOTDATA("Revenue",DatesCol!A1,"DateKey",1) -> 20
A13: DatesCol | B13: =GETPIVOTDATA("Revenue",DatesCol!A1,"DateKey",59) -> 30
A14: DatesCol | B14: =GETPIVOTDATA("Revenue",DatesCol!A1,"DateKey",60) -> 40
A15: DatesCol | B15: =GETPIVOTDATA("Revenue",DatesCol!A1,"DateKey",60.5) -> 50
A16: DatesCol | B16: =GETPIVOTDATA("Revenue",DatesCol!A1,"DateKey",43830) -> 600
A17: DatesCol | B17: =GETPIVOTDATA("Revenue",DatesCol!A1,"DateKey",43830.5) -> 70
A18: DatesCol | B18: =GETPIVOTDATA("Revenue",DatesCol!A1,"DateKey","(blank)") -> 90
A19: DatesNested | B19: =GETPIVOTDATA("Revenue",DatesNested!A1) -> 910
A20: DatesNested | B20: =GETPIVOTDATA("Revenue",DatesNested!A1,"DateKey",0) -> 10
A21: DatesNested | B21: =GETPIVOTDATA("Revenue",DatesNested!A1,"DateKey",1) -> 20
A22: DatesNested | B22: =GETPIVOTDATA("Revenue",DatesNested!A1,"DateKey",59) -> 30
A23: DatesNested | B23: =GETPIVOTDATA("Revenue",DatesNested!A1,"DateKey",60) -> 40
A24: DatesNested | B24: =GETPIVOTDATA("Revenue",DatesNested!A1,"DateKey",60.5) -> 50
A25: DatesNested | B25: =GETPIVOTDATA("Revenue",DatesNested!A1,"DateKey",43830) -> #REF!
A26: DatesNested | B26: =GETPIVOTDATA("Revenue",DatesNested!A1,"DateKey",43830.5) -> 70
A27: DatesNested | B27: =GETPIVOTDATA("Revenue",DatesNested!A1,"DateKey","(blank)") -> 90
A28: DatesNested | B28: =GETPIVOTDATA("Revenue",DatesNested!A1,"Group","South") -> 520
A29: DatesNested | B29: =GETPIVOTDATA("Revenue",DatesNested!A1,"Group","South","DateKey",43830) -> 430
A30: DatesOuterRows | B30: =GETPIVOTDATA("Revenue",DatesOuterRows!A1) -> 910
A31: DatesOuterRows | B31: =GETPIVOTDATA("Revenue",DatesOuterRows!A1,"DateKey",0) -> 10
A32: DatesOuterRows | B32: =GETPIVOTDATA("Revenue",DatesOuterRows!A1,"DateKey",1) -> 20
A33: DatesOuterRows | B33: =GETPIVOTDATA("Revenue",DatesOuterRows!A1,"DateKey",59) -> 30
A34: DatesOuterRows | B34: =GETPIVOTDATA("Revenue",DatesOuterRows!A1,"DateKey",60) -> 40
A35: DatesOuterRows | B35: =GETPIVOTDATA("Revenue",DatesOuterRows!A1,"DateKey",60.5) -> 50
A36: DatesOuterRows | B36: =GETPIVOTDATA("Revenue",DatesOuterRows!A1,"DateKey",43830) -> 600
A37: DatesOuterRows | B37: =GETPIVOTDATA("Revenue",DatesOuterRows!A1,"DateKey",43830.5) -> 70
A38: DatesOuterRows | B38: =GETPIVOTDATA("Revenue",DatesOuterRows!A1,"DateKey","(blank)") -> 90
A39: DatesOuterRows | B39: =GETPIVOTDATA("Revenue",DatesOuterRows!A1,"Group","South") -> #REF!
A40: DatesOuterRows | B40: =GETPIVOTDATA("Revenue",DatesOuterRows!A1,"Group","South","DateKey",43830) -> 430
...

Sheet Source
A1: Group | B1: DateKey | C1: MixedKey | D1: Amount | E1: Child
A2: North | B2: 0 | C2: 0 | D2: 10 | E2: Child1
A3: North | B3: 1 | C3: 1 | D3: 20 | E3: Child0
A4: North | B4: 59 | C4: 59 | D4: 30 | E4: Child1
A5: North | B5: 60 | C5: 60 | D5: 40 | E5: Child0
A6: North | B6: 60.5 | C6: 60.5 | D6: 50 | E6: Child1
A7: North | B7: 43830 | C7: 43830 | D7: 60 | E7: Child0
A8: North | B8: 43830.5 | C8: 43830.5 | D8: 70 | E8: Child1
A9: South | B9: 43830 | C9: 42 | D9: 60 | E9: Child0
A10: South | B10: 43830 | C10: 43830 | D10: 120 | E10: Child1
A11: South | B11: 43830 | C11: text | D11: 70 | E11: Child0
A12: South | B12: 43830 | C12: TRUE | D12: 80 | E12: Child1
A13: South | D13: 90 | E13: Child0
A14: South | B14: 43830 | C14: =1/0 -> #DIV/0! | D14: 100 | E14: Child1
A15: West | B15: 43830 | C15: #DIV/0! | D15: 110 | E15: Child0
